Workbook

Sheet 가이던스 상회 기업
A1: 기업명 | B1: 티커 | C1: 섹터(GICS) | D1: 주요 사업 | E1: 최근 분기(Q0) 종료일 | F1: Q0 실적 발표일 | G1: 매출 가이던스 하단 (백만$) | H1: 매출 가이던스 상단 (백만$) | I1: 가이던스 중앙값 (백만$) | J1: Q0 실제 매출 (백만$) | K1: 가이던스 중앙값 대비 | L1: 가이던스 상단 대비 | M1: 가이던스 형태 | N1: EPS 서프라이즈 (컨센서스 대비) | O1: 매출 Q0 (백만$) | P1: 매출 Q-1 (백만$) | Q1: 매출 Q-2 (백만$) | R1: 매출 Q-3 (백만$) | S1: 매출 Q-4 (백만$) | T1: 영업이익 Q0 (백만$) | U1: 영업이익 Q-1 (백만$) | V1: 영업이익 Q-2 (백만$) | W1: 영업이익 Q-3 (백만$) | X1: 영업이익 Q-4 (백만$) | Y1: 매출성장률(YoY) | Z1: 영업이익성장률(YoY) | AA1: 매출 QoQ(Q0) | AB1: 매출 QoQ(Q-1) | AC1: 매출 QoQ(Q-2) | AD1: 매출 QoQ(Q-3) | AE1: 주가 2025-09-25 ($) | AF1: 주가 2026-09-24 ($) | AG1: 1년 주가수익률 | AH1: PER (trailing) | AI1: Forward PER | AJ1: 가이던스 근거 문장 (직전 분기 실적 발표문) | AK1: SEC 공시
A2: Micron Technology | B2: MU | C2: Information Technology | D2: D램·낸드 메모리 반도체 제조 (AI 서버용 HBM 포함) | E2: 2026-05-31 | F2: 2026-06-24 | G2: 32750 | H2: 34250 | I2: 33500 | J2: 41456 | K2: =J2/I2-1 -> 0.23749254 | L2: =J2/H2-1 -> 0.21039416 | M2: ±금액 | N2: 0.2139 | O2: 41456 | P2: 23860 | Q2: 13643 | R2: 11315 | S2: 9301 | T2: 33318 | U2: 16135 | V2: 6136 | W2: 3693 | X2: 2169 | Y2: =IF(AND(ISNUMBER(O2),ISNUMBER(S2),S2<>0),O2/S2-1,"") -> 3.4571551 | Z2: 14.360996 | AA2: =IF(AND(ISNUMBER(O2),ISNUMBER(P2),P2<>0),O2/P2-1,"") -> 0.73746857 | AB2: =IF(AND(ISNUMBER(P2),ISNUMBER(Q2),Q2<>0),P2/Q2-1,"") -> 0.74888221 | AC2: =IF(AND(ISNUMBER(Q2),ISNUMBER(R2),R2<>0),Q2/R2-1,"") -> 0.20574459 | AD2: =IF(AND(ISNUMBER(R2),ISNUMBER(S2),S2<>0),R2/S2-1,"") -> 0.21653586 | AE2: 156.83 | AF2: 1080.53 | AG2: =IF(AND(ISNUMBER(AE2),ISNUMBER(AF2)),AF2/AE2-1,"") -> 5.8898171 | AH2: 24.677303 | AI2: 6.8372803 | AJ2: Revenue $33.5 billion ± $750 million $33.5 billion ± $750 million | AK2: 8-K 보기
A3: TD SYNNEX Corporation | B3: SNX | C3: Information Technology | D3: IT 하드웨어·소프트웨어 유통 | E3: 2026-05-31 | F3: 2026-06-25 | G3: 16100 | H3: 16900 | I3: 16500 | J3: 19574.813 | K3: =J3/I3-1 -> 0.1863523 | L3: =J3/H3-1 -> 0.15827296 | M3: 범위 | N3: 0.20799999 | O3: 19574.813 | P3: 17161.198 | Q3: 17379.14 | R3: 15650.924 | S3: 14946.315 | T3: 519.362 | U3: 489.36 | V3: 401.814 | W3: 385.961 | X3: 328.139 | Y3: =IF(AND(ISNUMBER(O3),ISNUMBER(S3),S3<>0),O3/S3-1,"") -> 0.30967486 | Z3: 0.58274999 | AA3: =IF(AND(ISNUMBER(O3),ISNUMBER(P3),P3<>0),O3/P3-1,"") -> 0.14064374 | AB3: =IF(AND(ISNUMBER(P3),ISNUMBER(Q3),Q3<>0),P3/Q3-1,"") -> -0.012540436 | AC3: =IF(AND(ISNUMBER(Q3),ISNUMBER(R3),R3<>0),Q3/R3-1,"") -> 0.11042262 | AD3: =IF(AND(ISNUMBER(R3),ISNUMBER(S3),S3<>0),R3/S3-1,"") -> 0.047142657 | AE3: 159.69 | AF3: 259.47 | AG3: =IF(AND(ISNUMBER(AE3),ISNUMBER(AF3)),AF3/AE3-1,"") -> 0.6248356 | AH3: 22.009539 | AI3: 12.651051 | AJ3: Revenue $16.1 - $16.9 billion | AK3: 8-K 보기
A4: Kratos Defense & Security Solut | B4: KTOS | C4: Industrials | D4: 군용 무인기·위성통신·미사일 등 방산 기술 | E4: 2026-06-30 | F4: 2026-08-04 | G4: 400 | H4: 410 | I4: 405 | J4: 458.8 | K4: =J4/I4-1 -> 0.13283951 | L4: =J4/H4-1 -> 0.11902439 | M4: 범위 | N4: 0.38369998 | O4: 458.8 | P4: 371 | Q4: 345.1 | R4: 347.6 | S4: 351.5 | T4: -0.8 | U4: 6.6 | V4: 10.1 | W4: 7.3 | X4: 3.7 | Y4: =IF(AND(ISNUMBER(O4),ISNUMBER(S4),S4<>0),O4/S4-1,"") -> 0.30526316 | Z4: 적자전환 | AA4: =IF(AND(ISNUMBER(O4),ISNUMBER(P4),P4<>0),O4/P4-1,"") -> 0.23665768 | AB4: =IF(AND(ISNUMBER(P4),ISNUMBER(Q4),Q4<>0),P4/Q4-1,"") -> 0.07505071 | AC4: =IF(AND(ISNUMBER(Q4),ISNUMBER(R4),R4<>0),Q4/R4-1,"") -> -0.0071921749 | AD4: =IF(AND(ISNUMBER(R4),ISNUMBER(S4),S4<>0),R4/S4-1,"") -> -0.011095306 | AE4: 84.199997 | AF4: 47.02 | AG4: =IF(AND(ISNUMBER(AE4),ISNUMBER(AF4)),AF4/AE4-1,"") -> -0.44156767 | AH4: 272.17648 | AI4: 42.017418 | AJ4: Revenues $400 - $410 $1,700 - $1,760 | AK4: 8-K 보기
A5: Intel | B5: INTC | C5: Information Technology | D5: PC·서버용 CPU 반도체 및 파운드리 | E5: 2026-06-30 | F5: 2026-07-23 | G5: 13800 | H5: 14800 | I5: 14300 | J5: 16128 | K5: =J5/I5-1 -> 0.12783217 | L5: =J5/H5-1 -> 0.08972973 | M5: 범위 | N5: 0.94589996 | O5: 16128 | P5: 13577 | Q5: 13674 | R5: 13653 | S5: 12859 | T5: 1966 | U5: 934 | V5: 550 | W5: 858 | X5: -1286 | Y5: =IF(AND(ISNUMBER(O5),ISNUMBER(S5),S5<>0),O5/S5-1,"") -> 0.25421884 | Z5: 흑자전환 | AA5: =IF(AND(ISNUMBER(O5),ISNUMBER(P5),P5<>0),O5/P5-1,"") -> 0.18789129 | AB5: =IF(AND(ISNUMBER(P5),ISNUMBER(Q5),Q5<>0),P5/Q5-1,"") -> -0.0070937546 | AC5: =IF(AND(ISNUMBER(Q5),ISNUMBER(R5),R5<>0),Q5/R5-1,"") -> 0.0015381235 | AD5: =IF(AND(ISNUMBER(R5),ISNUMBER(S5),S5<>0),R5/S5-1,"") -> 0.061746637 | AE5: 33.990002 | AF5: 127.39 | AG5: =IF(AND(ISNUMBER(AE5),ISNUMBER(AF5)),AF5/AE5-1,"") -> 2.7478668 | AI5: 60.81966 | AJ5: ▪ Forecasting second-quarter 2026 revenue of $13.8 billion to $14.8 billion; expecting second-quarter EPS attributable to Intel o f $0.08 and non-GAAP EPS attributable to Intel of $0.20. | AK5: 8-K 보기
A6: Sandisk | B6: SNDK | C6: Information Technology | D6: 낸드 플래시 메모리·SSD 등 데이터 저장장치 제조 (WD에서 분사) | E6: 2026-06-30 | F6: 2026-08-05 | G6: 7750 | H6: 8250 | I6: 8000 | J6: 8965 | K6: =J6/I6-1 -> 0.120625 | L6: =J6/H6-1 -> 0.086666667 | M6: 범위 | N6: 0.1372 | O6: 8965 | P6: 5950 | Q6: 3025 | R6: 2308 | S6: 1901 | T6: 7037 | U6: 4164 | V6: 1075 | W6: 192 | X6: 51 | Y6: =IF(AND(ISNUMBER(O6),ISNUMBER(S6),S6<>0),O6/S6-1,"") -> 3.715939 | Z6: 136.98039 | AA6: =IF(AND(ISNUMBER(O6),ISNUMBER(P6),P6<>0),O6/P6-1,"") -> 0.50672269 | AB6: =IF(AND(ISNUMBER(P6),ISNUMBER(Q6),Q6<>0),P6/Q6-1,"") -> 0.96694215 | AC6: =IF(AND(ISNUMBER(Q6),ISNUMBER(R6),R6<>0),Q6/R6-1,"") -> 0.31065858 | AD6: =IF(AND(ISNUMBER(R6),ISNUMBER(S6),S6<>0),R6/S6-1,"") -> 0.21409784 | AE6: 94.290001 | AF6: 1753.62 | AG6: =IF(AND(ISNUMBER(AE6),ISNUMBER(AF6)),AF6/AE6-1,"") -> 17.598154 | AH6: 23.994852 | AI6: 6.723481 | AJ6: • Expect fourth quarter revenue to be in the range of $7.75 billion to $8.25 billion, with expected Non-GAAP diluted net income per share to be in the range of $30.00 to $33.00. | AK6: 8-K 보기
A7: Forgent Power Solutions, Inc. | B7: FPS | C7: Industrials | D7: 데이터센터·전력망용 배전 장비 | E7: 2026-06-30 | F7: 2026-09-15 | G7: 392 | H7: 432 | I7: 412 | J7: 461.672 | K7: =J7/I7-1 -> 0.12056311 | L7: =J7/H7-1 -> 0.068685185 | M7: 범위 | N7: 0.0515 | O7: 461.672 | P7: 378.709 | Q7: 296.404 | R7: 283.274 | S7: 237.613 | T7: 91.9 | U7: 39.336 | V7: 20.09 | W7: 27.175 | X7: -27.388 | Y7: =IF(AND(ISNUMBER(O7),ISNUMBER(S7),S7<>0),O7/S7-1,"") -> 0.94295767 | Z7: 흑자전환 | AA7: =IF(AND(ISNUMBER(O7),ISNUMBER(P7),P7<>0),O7/P7-1,"") -> 0.21906794 | AB7: =IF(AND(ISNUMBER(P7),ISNUMBER(Q7),Q7<>0),P7/Q7-1,"") -> 0.27767844 | AC7: =IF(AND(ISNUMBER(Q7),ISNUMBER(R7),R7<>0),Q7/R7-1,"") -> 0.046350883 | AD7: =IF(AND(ISNUMBER(R7),ISNUMBER(S7),S7<>0),R7/S7-1,"") -> 0.19216541 | AG7: =IF(AND(ISNUMBER(AE7),ISNUMBER(AF7)),AF7/AE7-1,"") | AH7: 129.9 | AI7: 19.653826 | AJ7: Revenues $392 - $432 $1,350 - $1,390 | AK7: 8-K 보기
A8: Reddit | B8: RDDT | C8: Communication | D8: 온라인 커뮤니티 플랫폼 레딧 운영 (광고·데이터 라이선스) | E8: 2026-06-30 | F8: 2026-07-30 | G8: 715 | H8: 725 | I8: 720 | J8: 804.905 | K8: =J8/I8-1 -> 0.11792361 | L8: =J8/H8-1 -> 0.11021379 | M8: 범위 | N8: 0.2956 | O8: 804.905 | P8: 663.411 | Q8: 725.607 | R8: 584.911 | S8: 499.627 | T8: 231.716 | U8: 182.912 | V8: 231.828 | W8: 138.542 | X8: 67.711 | Y8: =IF(AND(ISNUMBER(O8),ISNUMBER(S8),S8<>0),O8/S8-1,"") -> 0.61101181 | Z8: 2.4221323 | AA8: =IF(AND(ISNUMBER(O8),ISNUMBER(P8),P8<>0),O8/P8-1,"") -> 0.21328257 | AB8: =IF(AND(ISNUMBER(P8),ISNUMBER(Q8),Q8<>0),P8/Q8-1,"") -> -0.085715821 | AC8: =IF(AND(ISNUMBER(Q8),ISNUMBER(R8),R8<>0),Q8/R8-1,"") -> 0.24054258 | AD8: =IF(AND(ISNUMBER(R8),ISNUMBER(S8),S8<>0),R8/S8-1,"") -> 0.17069534 | AE8: 232.75 | AF8: 152.72 | AG8: =IF(AND(ISNUMBER(AE8),ISNUMBER(AF8)),AF8/AE8-1,"") -> -0.34384532 | AH8: 35.429234 | AI8: 15.762596 | AJ8: • Revenue in the range of $715 million to $725 million | AK8: 8-K 보기
A9: Avnet, Inc. | B9: AVT | C9: Information Technology | D9: 전자부품 유통 | E9: 2026-06-30 | F9: 2026-08-05 | G9: 7300 | H9: 7600 | I9: 7450 | J9: 8295.377 | K9: =J9/I9-1 -> 0.11347342 | L9: =J9/H9-1 -> 0.091496974 | M9: 범위 | N9: 0.2881 | O9: 8295.377 | P9: 7119.779 | Q9: 6318.955 | R9: 5898.572 | S9: 5617.795 | T9: 317.526 | U9: 220.272 | V9: 171.367 | W9: 150.323 | X9: 142.513 | Y9: =IF(AND(ISNUMBER(O9),ISNUMBER(S9),S9<>0),O9/S9-1,"") -> 0.47662508 | Z9: 1.2280494 | AA9: =IF(AND(ISNUMBER(O9),ISNUMBER(P9),P9<>0),O9/P9-1,"") -> 0.1651172 | AB9: =IF(AND(ISNUMBER(P9),ISNUMBER(Q9),Q9<>0),P9/Q9-1,"") -> 0.12673361 | AC9: =IF(AND(ISNUMBER(Q9),ISNUMBER(R9),R9<>0),Q9/R9-1,"") -> 0.071268605 | AD9: =IF(AND(ISNUMBER(R9),ISNUMBER(S9),S9<>0),R9/S9-1,"") -> 0.04997993 | AE9: 51.57 | AF9: 100.91 | AG9: =IF(AND(ISNUMBER(AE9),ISNUMBER(AF9)),AF9/AE9-1,"") -> 0.95675789 | AH9: 25.87 | AI9: 9.367529 | AJ9: Sales ​ $7.30B – $7.60B | AK9: 8-K 보기
A10: Planet Labs PBC | B10: PL | C10: Industrials | D10: 지구관측 소형위성 영상 데이터 | E10: 2026-07-31 | F10: 2026-09-03 | G10: 102 | H10: 107 | I10: 104.5 | J10: 116.052 | K10: =J10/I10-1 -> 0.11054545 | L10: =J10/H10-1 -> 0.084598131 | M10: 범위 | N10: 1.9375999 | O10: 116.052 | P10: 94.15 | Q10: 86.822 | R10: 81.254 | S10: 73.386 | T10: -13.509 | U10: -34.888 | V10: -36.002 | W10: -18.34 | X10: -17.96 | Y10: =IF(AND(ISNUMBER(O10),ISNUMBER(S10),S10<>0),O10/S10-1,"") -> 0.58139155 | Z10: N/M | AA10: =IF(AND(ISNUMBER(O10),ISNUMBER(P10),P10<>0),O10/P10-1,"") -> 0.23262878 | AB10: =IF(AND(ISNUMBER(P10),ISNUMBER(Q10),Q10<>0),P10/Q10-1,"") -> 0.084402571 | AC10: =IF(AND(ISNUMBER(Q10),ISNUMBER(R10),R10<>0),Q10/R10-1,"") -> 0.068525857 | AD10: =IF(AND(ISNUMBER(R10),ISNUMBER(S10),S10<>0),R10/S10-1,"") -> 0.10721391 | AE10: 11.96 | AF10: 17.620001 | AG10: =IF(AND(ISNUMBER(AE10),ISNUMBER(AF10)),AF10/AE10-1,"") -> 0.47324421 | AJ10: For the second quarter of fiscal year 2027, ending July 31, 2026, Planet expects revenue to be in the range of approximately $102 million to $107 million. | AK10: 8-K 보기
A11: NetApp | B11: NTAP | C11: Information Technology | D11: 기업용 데이터 스토리지(올플래시·하이브리드 클라우드) 및 데이터 관리 소프트웨어 | E11: 2026-07-31 | F11: 2026-09-02 | G11: 1750 | H11: 1900 | I11: 1825 | J11: 2025 | K11: =J11/I11-1 -> 0.10958904 | L11: =J11/H11-1 -> 0.065789474 | M11: 범위 | N11: 0.21540001 | O11: 2025 | P11: 1948 | Q11: 1713 | R11: 1705 | S11: 1559 | T11: 540 | U11: 531 | V11: 431 | W11: 422 | X11: 311 | Y11: =IF(AND(ISNUMBER(O11),ISNUMBER(S11),S11<>0),O11/S11-1,"") -> 0.29890956 | Z11: 0.73633441 | AA11: =IF(AND(ISNUMBER(O11),ISNUMBER(P11),P11<>0),O11/P11-1,"") -> 0.039527721 | AB11: =IF(AND(ISNUMBER(P11),ISNUMBER(Q11),Q11<>0),P11/Q11-1,"") -> 0.13718622 | AC11: =IF(AND(ISNUMBER(Q11),ISNUMBER(R11),R11<>0),Q11/R11-1,"") -> 0.0046920821 | AD11: =IF(AND(ISNUMBER(R11),ISNUMBER(S11),S11<>0),R11/S11-1,"") -> 0.093649775 | AE11: 120.78 | AF11: 197.24001 | AG11: =IF(AND(ISNUMBER(AE11),ISNUMBER(AF11)),AF11/AE11-1,"") -> 0.63305189 | AH11: 28.12712 | AI11: 17.90676 | AJ11: Net revenues are expected to be in the range of: $1.750 billion - $1.900 billion | AK11: 8-K 보기
A12: Teradyne | B12: TER | C12: Information Technology | D12: 반도체·전자기기 자동 테스트 장비(ATE) 및 협동로봇 | E12: 2026-06-30 | F12: 2026-07-29 | G12: 1150 | H12: 1250 | I12: 1200 | J12: 1328.99 | K12: =J12/I12-1 -> 0.10749167 | L12: =J12/H12-1 -> 0.063192 | M12: 범위 | N12: 0.2028 | O12: 1328.99 | P12: 1282.494 | Q12: 1083.337 | R12: 769.21 | S12: 651.797 | T12: 440.842 | U12: 476.427 | V12: 308.283 | W12: 151.888 | X12: 93.115 | Y12: =IF(AND(ISNUMBER(O12),ISNUMBER(S12),S12<>0),O12/S12-1,"") -> 1.0389631 | Z12: 3.7343822 | AA12: =IF(AND(ISNUMBER(O12),ISNUMBER(P12),P12<>0),O12/P12-1,"") -> 0.036254361 | AB12: =IF(AND(ISNUMBER(P12),ISNUMBER(Q12),Q12<>0),P12/Q12-1,"") -> 0.18383661 | AC12: =IF(AND(ISNUMBER(Q12),ISNUMBER(R12),R12<>0),Q12/R12-1,"") -> 0.40837613 | AD12: =IF(AND(ISNUMBER(R12),ISNUMBER(S12),S12<>0),R12/S12-1,"") -> 0.18013737 | AE12: 132.87 | AF12: 387.70001 | AG12: =IF(AND(ISNUMBER(AE12),ISNUMBER(AF12)),AF12/AE12-1,"") -> 1.9178899 | AH12: 54.462276 | AI12: 34.072605 | AJ12: Guidance for the second quarter of 2026 is revenue of $1,150 million to $1,250 million, with GAAP net income of $1.83 to $2.12 per diluted share and non-GAAP net income of $1.86 to $2.15 per diluted share. | AK12: 8-K 보기
A13: James Hardie Industries plc. | B13: JHX | C13: Materials | D13: 섬유시멘트 사이딩·합성목재 데크(AZEK 인수) 등 건축 외장재 | E13: 2026-06-30 | F13: 2026-07-23 | G13: 1320 | H13: 1350 | I13: 1335 | J13: 1474.6 | K13: =J13/I13-1 -> 0.10456929 | L13: =J13/H13-1 -> 0.092296296 | M13: 범위 | O13: 1474.6 | P13: 1403.9 | Q13: 1239.8 | R13: 1292.2 | S13: 899.9 | T13: 237.9 | U13: 217.4 | V13: 181.9 | W13: 154.5 | X13: 168.7 | Y13: =IF(AND(ISNUMBER(O13),ISNUMBER(S13),S13<>0),O13/S13-1,"") -> 0.63862651 | Z13: 0.41019561 | AA13: =IF(AND(ISNUMBER(O13),ISNUMBER(P13),P13<>0),O13/P13-1,"") -> 0.050359712 | AB13: =IF(AND(ISNUMBER(P13),ISNUMBER(Q13),Q13<>0),P13/Q13-1,"") -> 0.13236006 | AC13: =IF(AND(ISNUMBER(Q13),ISNUMBER(R13),R13<>0),Q13/R13-1,"") -> -0.040550998 | AD13: =IF(AND(ISNUMBER(R13),ISNUMBER(S13),S13<>0),R13/S13-1,"") -> 0.43593733 | AE13: 18.59 | AF13: 26.1 | AG13: =IF(AND(ISNUMBER(AE13),ISNUMBER(AF13)),AF13/AE13-1,"") -> 0.40398064 | AH13: 118.90909 | AI13: 16.17981 | AJ13: • Total Net Sales: $1.32 to $1.35 billion | AK13: 8-K 보기
A14: Monolithic Power Systems | B14: MPWR | C14: Information Technology | D14: 전력관리 반도체(전원 IC) 설계 | E14: 2026-06-30 | F14: 2026-07-30 | G14: 890 | H14: 910 | I14: 900 | J14: 980.642 | K14: =J14/I14-1 -> 0.089602222 | L14: =J14/H14-1 -> 0.077628571 | M14: 범위 | N14: 0.10529999 | O14: 980.642 | P14: 804.185 | Q14: 751.155 | R14: 737.176 | S14: 664.574 | T14: 303.894 | U14: 241.152 | V14: 199.936 | W14: 195.183 | X14: 164.758 | Y14: =IF(AND(ISNUMBER(O14),ISNUMBER(S14),S14<>0),O14/S14-1,"") -> 0.47559489 | Z14: 0.84448707 | AA14: =IF(AND(ISNUMBER(O14),ISNUMBER(P14),P14<>0),O14/P14-1,"") -> 0.21942339 | AB14: =IF(AND(ISNUMBER(P14),ISNUMBER(Q14),Q14<>0),P14/Q14-1,"") -> 0.070597946 | AC14: =IF(AND(ISNUMBER(Q14),ISNUMBER(R14),R14<>0),Q14/R14-1,"") -> 0.018962907 | AD14: =IF(AND(ISNUMBER(R14),ISNUMBER(S14),S14<>0),R14/S14-1,"") -> 0.10924592 | AE14: 891.39001 | AF14: 1335.55 | AG14: =IF(AND(ISNUMBER(AE14),ISNUMBER(AF14)),AF14/AE14-1,"") -> 0.498278 | AH14: 82.99483 | AI14: 39.104607 | AJ14: Revenue in the range of $890 million to $910 million. | AK14: 8-K 보기
A15: Fortinet | B15: FTNT | C15: Information Technology | D15: 방화벽·네트워크 보안 장비 및 소프트웨어 | E15: 2026-06-30 | F15: 2026-07-29 | G15: 1830 | H15: 1930 | I15: 1880 | J15: 2047.9 | K15: =J15/I15-1 -> 0.089308511 | L15: =J15/H15-1 -> 0.061088083 | M15: 범위 | N15: 0.2053 | O15: 2047.9 | P15: 1849.6 | Q15: 1905 | R15: 1724.9 | S15: 1630 | T15: 689.3 | U15: 580 | V15: 625.6 | W15: 547.3 | X15: 458 | Y15: =IF(AND(ISNUMBER(O15),ISNUMBER(S15),S15<>0),O15/S15-1,"") -> 0.25638037 | Z15: 0.50502183 | AA15: =IF(AND(ISNUMBER(O15),ISNUMBER(P15),P15<>0),O15/P15-1,"") -> 0.10721237 | AB15: =IF(AND(ISNUMBER(P15),ISNUMBER(Q15),Q15<>0),P15/Q15-1,"") -> -0.029081365 | AC15: =IF(AND(ISNUMBER(Q15),ISNUMBER(R15),R15<>0),Q15/R15-1,"") -> 0.10441185 | AD15: =IF(AND(ISNUMBER(R15),ISNUMBER(S15),S15<>0),R15/S15-1,"") -> 0.058220859 | AE15: 83.209999 | AF15: 178.67 | AG15: =IF(AND(ISNUMBER(AE15),ISNUMBER(AF15)),AF15/AE15-1,"") -> 1.1472179 | AH15: 61.87057 | AI15: 46.184654 | AJ15: • Revenue in the range of $1.830 billion to $1.930 billion | AK15: 8-K 보기
A16: Lattice Semiconductor Corporati | B16: LSCC | C16: Information Technology | D16: 저전력 FPGA 반도체 | E16: 2026-06-30 | F16: 2026-08-04 | G16: 175 | H16: 195 | I16: 185 | J16: 201.079 | K16: =J16/I16-1 -> 0.086913514 | L16: =J16/H16-1 -> 0.031174359 | M16: 범위 | N16: 0.1906 | O16: 201.079 | P16: 170.897 | Q16: 145.792 | R16: 133.349 | S16: 123.971 | T16: 26.804 | U16: 26.671 | V16: 2.192 | W16: -0.528 | X16: 6.397 | Y16: =IF(AND(ISNUMBER(O16),ISNUMBER(S16),S16<>0),O16/S16-1,"") -> 0.62198417 | Z16: 3.1900891 | AA16: =IF(AND(ISNUMBER(O16),ISNUMBER(P16),P16<>0),O16/P16-1,"") -> 0.1766093 | AB16: =IF(AND(ISNUMBER(P16),ISNUMBER(Q16),Q16<>0),P16/Q16-1,"") -> 0.17219738 | AC16: =IF(AND(ISNUMBER(Q16),ISNUMBER(R16),R16<>0),Q16/R16-1,"") -> 0.093311536 | AD16: =IF(AND(ISNUMBER(R16),ISNUMBER(S16),S16<>0),R16/S16-1,"") -> 0.075646724 | AE16: 72.059998 | AF16: 122.22 | AG16: =IF(AND(ISNUMBER(AE16),ISNUMBER(AF16)),AF16/AE16-1,"") -> 0.69608667 | AH16: 528.1875 | AI16: 39.455624 | AJ16: Revenue for the second quarter of 2026 is expected to be between $175 million and $195 million. | AK16: 8-K 보기
A17: Arista Networks | B17: ANET | C17: Information Technology | D17: 데이터센터·AI 클러스터용 고속 네트워크 스위치 | E17: 2026-06-30 | F17: 2026-08-04 | G17: 2800 | H17: 2800 | I17: 2800 | J17: 3035.7 | K17: =J17/I17-1 -> 0.084178571 | L17: =J17/H17-1 -> 0.084178571 | M17: 단일값 | N17: 0.1518 | O17: 3035.7 | P17: 2709 | Q17: 2487.8 | R17: 2308.3 | S17: 2204.8 | T17: 1378 | U17: 1157.8 | V17: 1032.9 | W17: 978.2 | X17: 986.2 | Y17: =IF(AND(ISNUMBER(O17),ISNUMBER(S17),S17<>0),O17/S17-1,"") -> 0.37685958 | Z17: 0.3972825 | AA17: =IF(AND(ISNUMBER(O17),ISNUMBER(P17),P17<>0),O17/P17-1,"") -> 0.12059801 | AB17: =IF(AND(ISNUMBER(P17),ISNUMBER(Q17),Q17<>0),P17/Q17-1,"") -> 0.0889139 | AC17: =IF(AND(ISNUMBER(Q17),ISNUMBER(R17),R17<>0),Q17/R17-1,"") -> 0.077762856 | AD17: =IF(AND(ISNUMBER(R17),ISNUMBER(S17),S17<>0),R17/S17-1,"") -> 0.046943033 | AE17: 143.06 | AF17: 205.7 | AG17: =IF(AND(ISNUMBER(AE17),ISNUMBER(AF17)),AF17/AE17-1,"") -> 0.43785824 | AH17: 65.87619 | AI17: 40.002544 | AJ17: • Revenue of approximately $2.8 billion; | AK17: 8-K 보기
A18: Rubrik, Inc. | B18: RBRK | C18: Information Technology | D18: 데이터 보안·백업 소프트웨어 | E18: 2026-07-31 | F18: 2026-08-27 | G18: 395 | H18: 397 | I18: 396 | J18: 427.26 | K18: =J18/I18-1 -> 0.078939394 | L18: =J18/H18-1 -> 0.076221662 | M18: 범위 | N18: 4.0955 | O18: 427.26 | P18: 387.068 | Q18: 377.684 | R18: 350.166 | S18: 309.86 | T18: -71.902 | U18: -52.634 | V18: -82.379 | W18: -75.483 | X18: -94.463 | Y18: =IF(AND(ISNUMBER(O18),ISNUMBER(S18),S18<>0),O18/S18-1,"") -> 0.37888078 | Z18: N/M | AA18: =IF(AND(ISNUMBER(O18),ISNUMBER(P18),P18<>0),O18/P18-1,"") -> 0.10383705 | AB18: =IF(AND(ISNUMBER(P18),ISNUMBER(Q18),Q18<>0),P18/Q18-1,"") -> 0.024846168 | AC18: =IF(AND(ISNUMBER(Q18),ISNUMBER(R18),R18<>0),Q18/R18-1,"") -> 0.078585585 | AD18: =IF(AND(ISNUMBER(R18),ISNUMBER(S18),S18<>0),R18/S18-1,"") -> 0.1300781 | AE18: 81.989998 | AF18: 113.8 | AG18: =IF(AND(ISNUMBER(AE18),ISNUMBER(AF18)),AF18/AE18-1,"") -> 0.38797422 | AI18: 146.12128 | AJ18: ▪ Revenue of $395 million to $397 million. | AK18: 8-K 보기
A19: Everpure | B19: P | C19: Information Technology | D19: 기업용 올플래시 데이터 스토리지 (구 Pure Storage) | E19: 2026-07-31 | F19: 2026-08-26 | G19: 1095 | H19: 1105 | I19: 1100 | J19: 1185.898 | K19: =J19/I19-1 -> 0.078089091 | L19: =J19/H19-1 -> 0.07321086 | M19: 범위 | N19: 0.20969999 | O19: 1185.898 | P19: 1052.896 | Q19: 1058.903 | R19: 964.453 | S19: 861.002 | T19: 63.155 | U19: 19.939 | V19: 87.198 | W19: 53.918 | X19: 4.871 | Y19: =IF(AND(ISNUMBER(O19),ISNUMBER(S19),S19<>0),O19/S19-1,"") -> 0.37734639 | Z19: 11.96551 | AA19: =IF(AND(ISNUMBER(O19),ISNUMBER(P19),P19<>0),O19/P19-1,"") -> 0.12632017 | AB19: =IF(AND(ISNUMBER(P19),ISNUMBER(Q19),Q19<>0),P19/Q19-1,"") -> -0.005672852 | AC19: =IF(AND(ISNUMBER(Q19),ISNUMBER(R19),R19<>0),Q19/R19-1,"") -> 0.097931159 | AD19: =IF(AND(ISNUMBER(R19),ISNUMBER(S19),S19<>0),R19/S19-1,"") -> 0.12015187 | AE19: 83.470001 | AF19: 121.88 | AG19: =IF(AND(ISNUMBER(AE19),ISNUMBER(AF19)),AF19/AE19-1,"") -> 0.46016527 | AH19: 169.11644 | AI19: 34.77733 | AJ19: Revenue $1.095B to $1.105B | AK19: 8-K 보기
A20: FormFactor, Inc. | B20: FORM | C20: Information Technology | D20: 반도체 테스트용 프로브카드 | E20: 2026-06-30 | F20: 2026-07-29 | G20: 235 | H20: 245 | I20: 240 | J20: 258.242 | K20: =J20/I20-1 -> 0.076008333 | L20: =J20/H20-1 -> 0.05404898 | M20: ±금액 | N20: 0.3443 | O20: 258.242 | P20: 226.144 | Q20: 215.163 | R20: 202.676 | S20: 195.798 | T20: 62.658 | U20: 23.722 | V20: 25.194 | W20: 18.969 | X20: 12.663 | Y20: =IF(AND(ISNUMBER(O20),ISNUMBER(S20),S20<>0),O20/S20-1,"") -> 0.31892052 | Z20: 3.9481166 | AA20: =IF(AND(ISNUMBER(O20),ISNUMBER(P20),P20<>0),O20/P20-1,"") -> 0.14193611 | AB20: =IF(AND(ISNUMBER(P20),ISNUMBER(Q20),Q20<>0),P20/Q20-1,"") -> 0.051035726 | AC20: =IF(AND(ISNUMBER(Q20),ISNUMBER(R20),R20<>0),Q20/R20-1,"") -> 0.06161065 | AD20: =IF(AND(ISNUMBER(R20),ISNUMBER(S20),S20<>0),R20/S20-1,"") -> 0.03512804 | AE20: 35.599998 | AF20: 129.03999 | AG20: =IF(AND(ISNUMBER(AE20),ISNUMBER(AF20)),AF20/AE20-1,"") -> 2.6247191 | AH20: 91.47569 | AI20: 37.15797 | AJ20: Revenue $240 million +/- $5 million | AK20: 8-K 보기
A21: Palantir Technologies | B21: PLTR | C21: Information Technology | D21: 정부·기업용 빅데이터 분석 및 AI 소프트웨어 플랫폼 | E21: 2026-06-30 | F21: 2026-08-03 | G21: 1797 | H21: 1801 | I21: 1799 | J21: 1935.464 | K21: =J21/I21-1 -> 0.075855475 | L21: =J21/H21-1 -> 0.074660744 | M21: 범위 | N21: 0.1851 | O21: 1935.464 | P21: 1632.583 | Q21: 1406.802 | R21: 1181.092 | S21: 1003.697 | T21: 912.004 | U21: 753.998 | V21: 575.394 | W21: 393.256 | X21: 269.317 | Y21: =IF(AND(ISNUMBER(O21),ISNUMBER(S21),S21<>0),O21/S21-1,"") -> 0.92833495 | Z21: 2.3863588 | AA21: =IF(AND(ISNUMBER(O21),ISNUMBER(P21),P21<>0),O21/P21-1,"") -> 0.18552257 | AB21: =IF(AND(ISNUMBER(P21),ISNUMBER(Q21),Q21<>0),P21/Q21-1,"") -> 0.16049238 | AC21: =IF(AND(ISNUMBER(Q21),ISNUMBER(R21),R21<>0),Q21/R21-1,"") -> 0.19110281 | AD21: =IF(AND(ISNUMBER(R21),ISNUMBER(S21),S21<>0),R21/S21-1,"") -> 0.17674159 | AE21: 179.12 | AF21: 192.59 | AG21: =IF(AND(ISNUMBER(AE21),ISNUMBER(AF21)),AF21/AE21-1,"") -> 0.075200991 | AH21: 163.52138 | AI21: 82.359375 | AJ21: • Revenue of between $1.797 – $1.801 billion. | AK21: 8-K 보기
A22: Amphenol | B22: APH | C22: Information Technology | D22: 커넥터·케이블·센서 등 전자 연결 부품 | E22: 2026-06-30 | F22: 2026-07-29 | G22: 8100 | H22: 8200 | I22: 8150 | J22: 8758.1 | K22: =J22/I22-1 -> 0.074613497 | L22: =J22/H22-1 -> 0.068060976 | M22: 범위 | N22: 0.1319 | O22: 8758.1 | P22: 7620.1 | Q22: 6439 | R22: 6194.4 | S22: 5650.3 | T22: 2584.6 | U22: 1831.8 | V22: 1722.7 | W22: 1702.3 | X22: 1418.8 | Y22: =IF(AND(ISNUMBER(O22),ISNUMBER(S22),S22<>0),O22/S22-1,"") -> 0.55002389 | Z22: 0.82168029 | AA22: =IF(AND(ISNUMBER(O22),ISNUMBER(P22),P22<>0),O22/P22-1,"") -> 0.14934187 | AB22: =IF(AND(ISNUMBER(P22),ISNUMBER(Q22),Q22<>0),P22/Q22-1,"") -> 0.1834291 | AC22: =IF(AND(ISNUMBER(Q22),ISNUMBER(R22),R22<>0),Q22/R22-1,"") -> 0.039487279 | AD22: =IF(AND(ISNUMBER(R22),ISNUMBER(S22),S22<>0),R22/S22-1,"") -> 0.096295772 | AE22: 61.165001 | AF22: 83.080002 | AG22: =IF(AND(ISNUMBER(AE22),ISNUMBER(AF22)),AF22/AE22-1,"") -> 0.35829315 | AH22: 42.1925 | AI22: 25.724861 | AJ22: Assuming the continuation of current market conditions as well as constant exchange rates, for the second quarter of 2026, Amphenol expects sales to be in the range of $8.1 billion to $8.2 billion, representing a 43% to 45% increase over the prior year quarter. | AK22: 8-K 보기
A23: Unity Software Inc. | B23: U | C23: Information Technology | D23: 게임·실시간 3D 콘텐츠 개발 엔진 및 모바일 광고 플랫폼 | E23: 2026-06-30 | F23: 2026-08-06 | G23: 505 | H23: 515 | I23: 510 | J23: 546.468 | K23: =J23/I23-1 -> 0.071505882 | L23: =J23/H23-1 -> 0.061102913 | M23: 범위 | N23: 0.1241 | O23: 546.468 | P23: 508.238 | Q23: 503.089 | R23: 470.615 | S23: 440.944 | T23: -32.219 | U23: -351.413 | V23: -106.51 | W23: -125.856 | X23: -118.752 | Y23: =IF(AND(ISNUMBER(O23),ISNUMBER(S23),S23<>0),O23/S23-1,"") -> 0.23931384 | Z23: N/M | AA23: =IF(AND(ISNUMBER(O23),ISNUMBER(P23),P23<>0),O23/P23-1,"") -> 0.075220664 | AB23: =IF(AND(ISNUMBER(P23),ISNUMBER(Q23),Q23<>0),P23/Q23-1,"") -> 0.01023477 | AC23: =IF(AND(ISNUMBER(Q23),ISNUMBER(R23),R23<>0),Q23/R23-1,"") -> 0.069003325 | AD23: =IF(AND(ISNUMBER(R23),ISNUMBER(S23),S23<>0),R23/S23-1,"") -> 0.067289724 | AE23: 42.110001 | AF23: 41.419998 | AG23: =IF(AND(ISNUMBER(AE23),ISNUMBER(AF23)),AF23/AE23-1,"") -> -0.016385714 | AI23: 24.05296 | AJ23: • Total Revenue of $505 million to $515 million. | AK23: 8-K 보기
A24: Atlassian Corporation | B24: TEAM | C24: Information Technology | D24: 협업·개발자용 소프트웨어 (지라·컨플루언스) | E24: 2026-06-30 | F24: 2026-08-06 | G24: 1653 | H24: 1661 | I24: 1657 | J24: 1766.469 | K24: =J24/I24-1 -> 0.066064575 | L24: =J24/H24-1 -> 0.063497291 | M24: 범위 | N24: 0.24520001 | O24: 1766.469 | P24: 1786.971 | Q24: 1586.315 | R24: 1432.553 | S24: 1384.344 | T24: 210.723 | U24: -56.284 | V24: -47.747 | W24: -96.337 | X24: -28.479 | Y24: =IF(AND(ISNUMBER(O24),ISNUMBER(S24),S24<>0),O24/S24-1,"") -> 0.27603327 | Z24: 흑자전환 | AA24: =IF(AND(ISNUMBER(O24),ISNUMBER(P24),P24<>0),O24/P24-1,"") -> -0.011473046 | AB24: =IF(AND(ISNUMBER(P24),ISNUMBER(Q24),Q24<>0),P24/Q24-1,"") -> 0.1264919 | AC24: =IF(AND(ISNUMBER(Q24),ISNUMBER(R24),R24<>0),Q24/R24-1,"") -> 0.10733425 | AD24: =IF(AND(ISNUMBER(R24),ISNUMBER(S24),S24<>0),R24/S24-1,"") -> 0.034824437 | AE24: 162.42 | AF24: 192.61 | AG24: =IF(AND(ISNUMBER(AE24),ISNUMBER(AF24)),AF24/AE24-1,"") -> 0.18587614 | AI24: 28.56833 | AJ24: Q3 FY26 18 Q4’26 Outlook TOTAL REVENUE For Q4’26, we expect total company revenue to be in the range of $1,653 million to $1,661 million. | AK24: 8-K 보기
A25: Entegris, Inc. | B25: ENTG | C25: Information Technology | D25: 반도체 공정용 특수소재·필터·웨이퍼 취급 용기 | E25: 2026-06-30 | F25: 2026-08-04 | G25: 815 | H25: 845 | I25: 830 | J25: 883.2 | K25: =J25/I25-1 -> 0.064096386 | L25: =J25/H25-1 -> 0.045207101 | M25: 범위 | N25: 0.1321 | O25: 883.2 | P25: 811.9 | Q25: 823.9 | R25: 807.1 | S25: 792.4 | T25: 159.8 | U25: 141.6 | V25: 569.5 | W25: 123 | X25: 106.1 | Y25: =IF(AND(ISNUMBER(O25),ISNUMBER(S25),S25<>0),O25/S25-1,"") -> 0.11458859 | Z25: 0.5061263 | AA25: =IF(AND(ISNUMBER(O25),ISNUMBER(P25),P25<>0),O25/P25-1,"") -> 0.087818697 | AB25: =IF(AND(ISNUMBER(P25),ISNUMBER(Q25),Q25<>0),P25/Q25-1,"") -> -0.014564874 | AC25: =IF(AND(ISNUMBER(Q25),ISNUMBER(R25),R25<>0),Q25/R25-1,"") -> 0.020815265 | AD25: =IF(AND(ISNUMBER(R25),ISNUMBER(S25),S25<>0),R25/S25-1,"") -> 0.018551237 | AE25: 91.940002 | AF25: 148.63 | AG25: =IF(AND(ISNUMBER(AE25),ISNUMBER(AF25)),AF25/AE25-1,"") -> 0.61659779 | AH25: 75.76119 | AI25: 30.36091 | AJ25: For the Company’s guidance for the second quarter ending June 27, 2026, the Company expects sales of $815 million to $845 million. | AK25: 8-K 보기
A26: Advanced Energy Industries, Inc | B26: AEIS | C26: Information Technology | D26: 반도체 장비·데이터센터용 정밀 전력 변환 장치 | E26: 2026-06-30 | F26: 2026-08-03 | G26: 520 | H26: 560 | I26: 540 | J26: 574.1 | K26: =J26/I26-1 -> 0.063148148 | L26: =J26/H26-1 -> 0.025178571 | M26: ±금액 | N26: 0.23799999 | O26: 574.1 | P26: 511 | Q26: 489.4 | R26: 463.3 | S26: 441.5 | T26: 95.1 | U26: 68.3 | V26: 56.6 | W26: 49.2 | X26: 31.6 | Y26: =IF(AND(ISNUMBER(O26),ISNUMBER(S26),S26<>0),O26/S26-1,"") -> 0.30033975 | Z26: 2.0094937 | AA26: =IF(AND(ISNUMBER(O26),ISNUMBER(P26),P26<>0),O26/P26-1,"") -> 0.12348337 | AB26: =IF(AND(ISNUMBER(P26),ISNUMBER(Q26),Q26<>0),P26/Q26-1,"") -> 0.044135676 | AC26: =IF(AND(ISNUMBER(Q26),ISNUMBER(R26),R26<>0),Q26/R26-1,"") -> 0.056334988 | AD26: =IF(AND(ISNUMBER(R26),ISNUMBER(S26),S26<>0),R26/S26-1,"") -> 0.049377123 | AE26: 167.35001 | AF26: 278.03 | AG26: =IF(AND(ISNUMBER(AE26),ISNUMBER(AF26)),AF26/AE26-1,"") -> 0.66136832 | AH26: 52.740738 | AI26: 18.566166 | AJ26: Revenue $540 million +/- $20 million | AK26: 8-K 보기
A27: Solstice Advanced Materials Inc | B27: SOLS | C27: Materials | D27: 냉매·반도체 소재 등 특수화학 (하니웰 분사) | E27: 2026-06-30 | F27: 2026-07-30 | G27: 1060 | H27: 1100 | I27: 1080 | J27: 1148 | K27: =J27/I27-1 -> 0.062962963 | L27: =J27/H27-1 -> 0.043636364 | M27: 범위 | N27: 0.1375 | O27: 1148 | P27: 992 | Q27: 987 | R27: 969 | S27: 1033 | T27: 222 | U27: 181 | V27: 119 | W27: 171 | X27: 233 | Y27: =IF(AND(ISNUMBER(O27),ISNUMBER(S27),S27<>0),O27/S27-1,"") -> 0.11132623 | Z27: -0.0472103 | AA27: =IF(AND(ISNUMBER(O27),ISNUMBER(P27),P27<>0),O27/P27-1,"") -> 0.15725806 | AB27: =IF(AND(ISNUMBER(P27),ISNUMBER(Q27),Q27<>0),P27/Q27-1,"") -> 0.0050658561 | AC27: =IF(AND(ISNUMBER(Q27),ISNUMBER(R27),R27<>0),Q27/R27-1,"") -> 0.018575851 | AD27: =IF(AND(ISNUMBER(R27),ISNUMBER(S27),S27<>0),R27/S27-1,"") -> -0.06195547 | AG27: =IF(AND(ISNUMBER(AE27),ISNUMBER(AF27)),AF27/AE27-1,"") | AH27: 42.700756 | AI27: 16.70371 | AJ27: • Net Sales in a range of $1.06 billion to $1.1 billion; and • Adjusted EBITDA Margin 1 in a range of 25% to 26%. | AK27: 8-K 보기
A28: Keysight Technologies | B28: KEYS | C28: Information Technology | D28: 전자 계측·시험 장비 및 설계 소프트웨어 | E28: 2026-07-31 | F28: 2026-08-18 | G28: 1730 | H28: 1750 | I28: 1740 | J28: 1846 | K28: =J28/I28-1 -> 0.06091954 | L28: =J28/H28-1 -> 0.054857143 | M28: 범위 | N28: 0.2369 | O28: 1846 | P28: 1717 | Q28: 1600 | R28: 1419 | S28: 1352 | T28: 461 | U28: 407 | V28: 248 | W28: 217 | X28: 234 | Y28: =IF(AND(ISNUMBER(O28),ISNUMBER(S28),S28<>0),O28/S28-1,"") -> 0.36538462 | Z28: 0.97008547 | AA28: =IF(AND(ISNUMBER(O28),ISNUMBER(P28),P28<>0),O28/P28-1,"") -> 0.075131043 | AB28: =IF(AND(ISNUMBER(P28),ISNUMBER(Q28),Q28<>0),P28/Q28-1,"") -> 0.073125 | AC28: =IF(AND(ISNUMBER(Q28),ISNUMBER(R28),R28<>0),Q28/R28-1,"") -> 0.12755462 | AD28: =IF(AND(ISNUMBER(R28),ISNUMBER(S28),S28<>0),R28/S28-1,"") -> 0.049556213 | AE28: 172.33 | AF28: 357.54001 | AG28: =IF(AND(ISNUMBER(AE28),ISNUMBER(AF28)),AF28/AE28-1,"") -> 1.0747404 | AH28: 49.055405 | AI28: 26.169353 | AJ28: Keysight’s third fiscal quarter of 2026 revenue is expected to be in the range of $1.730 billion to $1.750 billion. | AK28: 8-K 보기
A29: Figma, Inc. | B29: FIG | C29: Information Technology | D29: 협업형 디자인 소프트웨어 (피그마) | E29: 2026-06-30 | F29: 2026-08-05 | G29: 348 | H29: 350 | I29: 349 | J29: 370.083 | K29: =J29/I29-1 -> 0.060409742 | L29: =J29/H29-1 -> 0.05738 | M29: 범위 | N29: 0.9593 | O29: 370.083 | P29: 333.439 | Q29: 303.776 | R29: 274.173 | S29: 249.64 | T29: -117.289 | U29: -137.398 | V29: -195.502 | W29: -1136.78 | X29: 2.076 | Y29: =IF(AND(ISNUMBER(O29),ISNUMBER(S29),S29<>0),O29/S29-1,"") -> 0.48246675 | Z29: 적자전환 | AA29: =IF(AND(ISNUMBER(O29),ISNUMBER(P29),P29<>0),O29/P29-1,"") -> 0.10989716 | AB29: =IF(AND(ISNUMBER(P29),ISNUMBER(Q29),Q29<>0),P29/Q29-1,"") -> 0.097647609 | AC29: =IF(AND(ISNUMBER(Q29),ISNUMBER(R29),R29<>0),Q29/R29-1,"") -> 0.10797197 | AD29: =IF(AND(ISNUMBER(R29),ISNUMBER(S29),S29<>0),R29/S29-1,"") -> 0.098273514 | AE29: 54.389999 | AF29: 21.34 | AG29: =IF(AND(ISNUMBER(AE29),ISNUMBER(AF29)),AF29/AE29-1,"") -> -0.60764846 | AI29: 60.74286 | AJ29: • Revenue between $348.0 million and $350.0 million, implying 40% year-over-year growth at the midpoint of the range. | AK29: 8-K 보기
A30: Five Below, Inc. | B30: FIVE | C30: Consumer Discretionary | D30: 10대·청소년 대상 저가 잡화 할인점 (Five Below) | E30: 2026-07-31 | F30: 2026-09-02 | G30: 1180 | H30: 1200 | I30: 1190 | J30: 1261.493 | K30: =J30/I30-1 -> 0.060078151 | L30: =J30/H30-1 -> 0.051244167 | M30: 범위 | N30: 0.1929 | O30: 1261.493 | P30: 1285.602 | Q30: 1728.48 | R30: 1038.293 | S30: 1026.847 | T30: 275.35 | U30: 154.243 | V30: 310.882 | W30: 43.305 | X30: 52.365 | Y30: =IF(AND(ISNUMBER(O30),ISNUMBER(S30),S30<>0),O30/S30-1,"") -> 0.22851116 | Z30: 4.2582832 | AA30: =IF(AND(ISNUMBER(O30),ISNUMBER(P30),P30<>0),O30/P30-1,"") -> -0.018753082 | AB30: =IF(AND(ISNUMBER(P30),ISNUMBER(Q30),Q30<>0),P30/Q30-1,"") -> -0.25622397 | AC30: =IF(AND(ISNUMBER(Q30),ISNUMBER(R30),R30<>0),Q30/R30-1,"") -> 0.6647324 | AD30: =IF(AND(ISNUMBER(R30),ISNUMBER(S30),S30<>0),R30/S30-1,"") -> 0.011146743 | AE30: 151.72 | AF30: 222.38 | AG30: =IF(AND(ISNUMBER(AE30),ISNUMBER(AF30)),AF30/AE30-1,"") -> 0.46572636 | AH30: 19.675337 | AI30: 19.830065 | AJ30: • Net sales are expected to be in the range of $1.18 billion to $1.20 billion based on opening approximately 50 new stores and assumes an approximate 7% to 9% increase in comparable sales. | AK30: 8-K 보기
A31: Arrow Electronics, Inc. | B31: ARW | C31: Information Technology | D31: 전자부품·기업용 IT 솔루션 유통 | E31: 2026-06-30 | F31: 2026-08-06 | G31: 9150 | H31: 9750 | I31: 9450 | J31: 9992.237 | K31: =J31/I31-1 -> 0.057379577 | L31: =J31/H31-1 -> 0.024844821 | M31: 범위 | N31: 0.222 | O31: 9992.237 | P31: 9473.548 | Q31: 8746.43 | R31: 7712.541 | S31: 7579.947 | T31: 401.472 | U31: 398.266 | V31: 335.316 | W31: 214.655 | X31: 212.505 | Y31: =IF(AND(ISNUMBER(O31),ISNUMBER(S31),S31<>0),O31/S31-1,"") -> 0.31824629 | Z31: 0.88923555 | AA31: =IF(AND(ISNUMBER(O31),ISNUMBER(P31),P31<>0),O31/P31-1,"") -> 0.054751293 | AB31: =IF(AND(ISNUMBER(P31),ISNUMBER(Q31),Q31<>0),P31/Q31-1,"") -> 0.083133118 | AC31: =IF(AND(ISNUMBER(Q31),ISNUMBER(R31),R31<>0),Q31/R31-1,"") -> 0.13405297 | AD31: =IF(AND(ISNUMBER(R31),ISNUMBER(S31),S31<>0),R31/S31-1,"") -> 0.017492734 | AE31: 118.84 | AF31: 227.33 | AG31: =IF(AND(ISNUMBER(AE31),ISNUMBER(AF31)),AF31/AE31-1,"") -> 0.91290819 | AH31: 14.76982 | AI31: 9.655172 | AJ31: ● C onsolidated sales of $9.15 billion to $9.75 billion, with global components sales of $6.80 billion to $7.20 billion, and global enterprise computing solutions sales of $2.35 billion to $2.55 billion | AK31: 8-K 보기
A32: Nvidia | B32: NVDA | C32: Information Technology | D32: AI 가속기(GPU)·데이터센터 플랫폼 및 게이밍 GPU | E32: 2026-07-31 | F32: 2026-08-26 | G32: 89180 | H32: 92820 | I32: 91000 | J32: 96221 | K32: =J32/I32-1 -> 0.057373626 | L32: =J32/H32-1 -> 0.03664081 | M32: ±% | N32: 0.0616 | O32: 96221 | P32: 81615 | Q32: 68127 | R32: 57006 | S32: 46743 | T32: 63734 | U32: 53536 | V32: 44299 | W32: 36010 | X32: 28440 | Y32: =IF(AND(ISNUMBER(O32),ISNUMBER(S32),S32<>0),O32/S32-1,"") -> 1.0585114 | Z32: 1.2409986 | AA32: =IF(AND(ISNUMBER(O32),ISNUMBER(P32),P32<>0),O32/P32-1,"") -> 0.1789622 | AB32: =IF(AND(ISNUMBER(P32),ISNUMBER(Q32),Q32<>0),P32/Q32-1,"") -> 0.19798318 | AC32: =IF(AND(ISNUMBER(Q32),ISNUMBER(R32),R32<>0),Q32/R32-1,"") -> 0.19508473 | AD32: =IF(AND(ISNUMBER(R32),ISNUMBER(S32),S32<>0),R32/S32-1,"") -> 0.21956229 | AE32: 177.69 | AF32: 224.58 | AG32: =IF(AND(ISNUMBER(AE32),ISNUMBER(AF32)),AF32/AE32-1,"") -> 0.26388654 | AH32: 28.397598 | AI32: 14.323172 | AJ32: • Revenue is expected to be $91.0 billion, plus or minus 2%. | AK32: 8-K 보기
A33: Flex Ltd. | B33: FLEX | C33: Information Technology | D33: 전자제품 위탁생산(EMS) 및 데이터센터 전력 장비 | E33: 2026-06-26 | F33: 2026-07-29 | G33: 7350 | H33: 7650 | I33: 7500 | J33: 7928 | K33: =J33/I33-1 -> 0.057066667 | L33: =J33/H33-1 -> 0.036339869 | M33: 범위 | N33: 0.088999994 | O33: 7928 | P33: 7477 | Q33: 7058 | R33: 6804 | S33: 6575 | T33: 392 | U33: 372 | V33: 389 | W33: 296 | X33: 311 | Y33: =IF(AND(ISNUMBER(O33),ISNUMBER(S33),S33<>0),O33/S33-1,"") -> 0.20577947 | Z33: 0.26045016 | AA33: =IF(AND(ISNUMBER(O33),ISNUMBER(P33),P33<>0),O33/P33-1,"") -> 0.060318309 | AB33: =IF(AND(ISNUMBER(P33),ISNUMBER(Q33),Q33<>0),P33/Q33-1,"") -> 0.059365259 | AC33: =IF(AND(ISNUMBER(Q33),ISNUMBER(R33),R33<>0),Q33/R33-1,"") -> 0.037330982 | AD33: =IF(AND(ISNUMBER(R33),ISNUMBER(S33),S33<>0),R33/S33-1,"") -> 0.034828897 | AE33: 56.5 | AF33: 112.4 | AG33: =IF(AND(ISNUMBER(AE33),ISNUMBER(AF33)),AF33/AE33-1,"") -> 0.98938056 | AH33: 46.166668 | AI33: 16.749846 | AJ33: • Net Sales: $7.35 billion to $7.65 billion, growth of 14% at the midpoint | AK33: 8-K 보기
A34: Trex Company, Inc. | B34: TREX | C34: Industrials | D34: 합성목재 데크·난간 | E34: 2026-06-30 | F34: 2026-08-04 | G34: 388 | H34: 403 | I34: 395.5 | J34: 418.019 | K34: =J34/I34-1 -> 0.056938053 | L34: =J34/H34-1 -> 0.03726799 | M34: 범위 | N34: -0.0207 | O34: 418.019 | P34: 343.403 | Q34: 161.125 | R34: 285.348 | S34: 387.801 | T34: 86.192 | U34: 83.505 | V34: 3.502 | W34: 70.397 | X34: 102.398 | Y34: =IF(AND(ISNUMBER(O34),ISNUMBER(S34),S34<>0),O34/S34-1,"") -> 0.077921408 | Z34: -0.15826481 | AA34: =IF(AND(ISNUMBER(O34),ISNUMBER(P34),P34<>0),O34/P34-1,"") -> 0.21728407 | AB34: =IF(AND(ISNUMBER(P34),ISNUMBER(Q34),Q34<>0),P34/Q34-1,"") -> 1.1312832 | AC34: =IF(AND(ISNUMBER(Q34),ISNUMBER(R34),R34<>0),Q34/R34-1,"") -> -0.4353386 | AD34: =IF(AND(ISNUMBER(R34),ISNUMBER(S34),S34<>0),R34/S34-1,"") -> -0.26418962 | AE34: 50.48 | AF34: 43.220001 | AG34: =IF(AND(ISNUMBER(AE34),ISNUMBER(AF34)),AF34/AE34-1,"") -> -0.1438193 | AH34: 25.255882 | AI34: 21.279709 | AJ34: For the second quarter, we expect net sales in the range of $388 million to $403 million, and we expect to see a reversal of the gross margin benefit from product mix that we saw in Q1. | AK34: 8-K 보기
A35: TTM Technologies, Inc. | B35: TTMI | C35: Information Technology | D35: 인쇄회로기판(PCB) 및 방산 RF 부품 | E35: 2026-06-30 | F35: 2026-08-06 | G35: 930 | H35: 970 | I35: 950 | J35: 1004.054 | K35: =J35/I35-1 -> 0.056898947 | L35: =J35/H35-1 -> 0.035107216 | M35: 범위 | N35: 0.1031 | O35: 1004.054 | P35: 845.976 | Q35: 774.32 | R35: 752.736 | S35: 730.621 | T35: 109.395 | U35: 72.745 | V35: 80.965 | W35: 72.415 | X35: 63.177 | Y35: =IF(AND(ISNUMBER(O35),ISNUMBER(S35),S35<>0),O35/S35-1,"") -> 0.37424739 | Z35: 0.7315637 | AA35: =IF(AND(ISNUMBER(O35),ISNUMBER(P35),P35<>0),O35/P35-1,"") -> 0.18685873 | AB35: =IF(AND(ISNUMBER(P35),ISNUMBER(Q35),Q35<>0),P35/Q35-1,"") -> 0.092540552 | AC35: =IF(AND(ISNUMBER(Q35),ISNUMBER(R35),R35<>0),Q35/R35-1,"") -> 0.028674064 | AD35: =IF(AND(ISNUMBER(R35),ISNUMBER(S35),S35<>0),R35/S35-1,"") -> 0.030268771 | AE35: 54.509998 | AF35: 126.98 | AG35: =IF(AND(ISNUMBER(AE35),ISNUMBER(AF35)),AF35/AE35-1,"") -> 1.329481 | AH35: 58.024776 | AI35: 18.689156 | AJ35: second quarter of 2026, TTM estimates that net sales will be in the range of $930 million to $970 million, and non-GAAP net income will be in the range of $0.82 to $0.88 per diluted share. | AK35: 8-K 보기
A36: Onto Innovation Inc. | B36: ONTO | C36: Information Technology | D36: 반도체 검사·계측 및 리소그래피 장비 | E36: 2026-06-30 | F36: 2026-08-06 | G36: 320 | H36: 330 | I36: 325 | J36: 343.129 | K36: =J36/I36-1 -> 0.055781538 | L36: =J36/H36-1 -> 0.039784848 | M36: 범위 | N36: 0.1415 | O36: 343.129 | P36: 291.949 | Q36: 266.866 | R36: 218.193 | S36: 253.597 | T36: 67.311 | U36: 38.723 | V36: 20.861 | W36: 27.762 | X36: 38.471 | Y36: =IF(AND(ISNUMBER(O36),ISNUMBER(S36),S36<>0),O36/S36-1,"") -> 0.35304834 | Z36: 0.74965558 | AA36: =IF(AND(ISNUMBER(O36),ISNUMBER(P36),P36<>0),O36/P36-1,"") -> 0.17530459 | AB36: =IF(AND(ISNUMBER(P36),ISNUMBER(Q36),Q36<>0),P36/Q36-1,"") -> 0.093990992 | AC36: =IF(AND(ISNUMBER(Q36),ISNUMBER(R36),R36<>0),Q36/R36-1,"") -> 0.22307315 | AD36: =IF(AND(ISNUMBER(R36),ISNUMBER(S36),S36<>0),R36/S36-1,"") -> -0.13960733 | AE36: 127.93 | AF36: 279.73001 | AG36: =IF(AND(ISNUMBER(AE36),ISNUMBER(AF36)),AF36/AE36-1,"") -> 1.1865865 | AH36: 108.06578 | AI36: 24.4505 | AJ36: • Revenue of $320 million to $330 million | AK36: 8-K 보기
A37: Dell Technologies | B37: DELL | C37: Information Technology | D37: PC·서버(AI 서버)·스토리지 | E37: 2026-07-31 | F37: 2026-09-01 | G37: 44000 | H37: 45000 | I37: 44500 | J37: 46971 | K37: =J37/I37-1 -> 0.05552809 | L37: =J37/H37-1 -> 0.0438 | M37: 범위 | N37: 0.4314 | O37: 46971 | P37: 43842 | Q37: 33379 | R37: 27005 | S37: 29776 | T37: 5472 | U37: 3762 | V37: 3145 | W37: 2168 | X37: 1901 | Y37: =IF(AND(ISNUMBER(O37),ISNUMBER(S37),S37<>0),O37/S37-1,"") -> 0.57747851 | Z37: 1.878485 | AA37: =IF(AND(ISNUMBER(O37),ISNUMBER(P37),P37<>0),O37/P37-1,"") -> 0.071369919 | AB37: =IF(AND(ISNUMBER(P37),ISNUMBER(Q37),Q37<>0),P37/Q37-1,"") -> 0.31346056 | AC37: =IF(AND(ISNUMBER(Q37),ISNUMBER(R37),R37<>0),Q37/R37-1,"") -> 0.23603036 | AD37: =IF(AND(ISNUMBER(R37),ISNUMBER(S37),S37<>0),R37/S37-1,"") -> -0.093061526 | AE37: 130.96001 | AF37: 536.02002 | AG37: =IF(AND(ISNUMBER(AE37),ISNUMBER(AF37)),AF37/AE37-1,"") -> 3.0930054 | AH37: 32.1412 | AI37: 18.997408 | AJ37: • Second-quarter FY27 revenue expected between $44.0 billion and $45.0 billion, up 49% year over year at the midpoint of $44.5 billion | AK37: 8-K 보기
A38: Littelfuse, Inc. | B38: LFUS | C38: Information Technology | D38: 퓨즈·전력 반도체 등 회로보호 부품 | E38: 2026-06-30 | F38: 2026-07-29 | G38: 690 | H38: 710 | I38: 700 | J38: 738.781 | K38: =J38/I38-1 -> 0.055401429 | L38: =J38/H38-1 -> 0.04053662 | M38: 범위 | N38: 0.1075 | O38: 738.781 | P38: 656.969 | Q38: 593.934 | R38: 624.64 | S38: 613.413 | T38: 139.745 | U38: 108.587 | V38: 84.076 | W38: 99.049 | X38: 95.284 | Y38: =IF(AND(ISNUMBER(O38),ISNUMBER(S38),S38<>0),O38/S38-1,"") -> 0.2043778 | Z38: 0.46661559 | AA38: =IF(AND(ISNUMBER(O38),ISNUMBER(P38),P38<>0),O38/P38-1,"") -> 0.12452947 | AB38: =IF(AND(ISNUMBER(P38),ISNUMBER(Q38),Q38<>0),P38/Q38-1,"") -> 0.10613132 | AC38: =IF(AND(ISNUMBER(Q38),ISNUMBER(R38),R38<>0),Q38/R38-1,"") -> -0.049157915 | AD38: =IF(AND(ISNUMBER(R38),ISNUMBER(S38),S38<>0),R38/S38-1,"") -> 0.018302514 | AE38: 257.75 | AF38: 421.16 | AG38: =IF(AND(ISNUMBER(AE38),ISNUMBER(AF38)),AF38/AE38-1,"") -> 0.63398644 | AI38: 21.214134 | AJ38: 13Littelfuse, Inc. © 2026 Q2 2026 GUIDANCE  Entered Q2 with a strong backlog and continued bookings momentum  Focused on execution, traction on strategic priorities  Q2 sales guidance: $690m - $710m  +7% sequential  +14% yr/yr; +8% organic  +6% yr/yr growth from the Basler acquisition  Adj. | AK38: 8-K 보기
A39: MongoDB, Inc. | B39: MDB | C39: Information Technology | D39: NoSQL 데이터베이스 플랫폼 (MongoDB Atlas) | E39: 2026-07-31 | F39: 2026-09-01 | G39: 729 | H39: 734 | I39: 731.5 | J39: 771.773 | K39: =J39/I39-1 -> 0.055055366 | L39: =J39/H39-1 -> 0.051461853 | M39: 범위 | N39: 0.18090001 | O39: 771.773 | P39: 687.616 | Q39: 695.072 | R39: 628.309 | S39: 591.402 | T39: 28.4 | U39: -24.804 | V39: 0.304 | W39: -18.424 | X39: -65.294 | Y39: =IF(AND(ISNUMBER(O39),ISNUMBER(S39),S39<>0),O39/S39-1,"") -> 0.30498882 | Z39: 흑자전환 | AA39: =IF(AND(ISNUMBER(O39),ISNUMBER(P39),P39<>0),O39/P39-1,"") -> 0.12238953 | AB39: =IF(AND(ISNUMBER(P39),ISNUMBER(Q39),Q39<>0),P39/Q39-1,"") -> -0.010726946 | AC39: =IF(AND(ISNUMBER(Q39),ISNUMBER(R39),R39<>0),Q39/R39-1,"") -> 0.10625823 | AD39: =IF(AND(ISNUMBER(R39),ISNUMBER(S39),S39<>0),R39/S39-1,"") -> 0.062405944 | AE39: 315.32001 | AF39: 421.39999 | AG39: =IF(AND(ISNUMBER(AE39),ISNUMBER(AF39)),AF39/AE39-1,"") -> 0.33642009 | AH39: 584.5416 | AI39: 54.008514 | AJ39: Revenues are expected to be in the range of: $729 million to $734 million | AK39: 8-K 보기
A40: Nordson Corporation | B40: NDSN | C40: Industrials | D40: 정밀 접착제·코팅 도포 장비 | E40: 2026-07-31 | F40: 2026-08-19 | G40: 760 | H40: 790 | I40: 775 | J40: 817.667 | K40: =J40/I40-1 -> 0.055054194 | L40: =J40/H40-1 -> 0.035021519 | M40: 범위 | N40: 0.050300002 | O40: 817.667 | P40: 740.847 | Q40: 669.461 | R40: 751.82 | S40: 741.509 | T40: 223.092 | U40: 197.203 | V40: 166.405 | W40: 214.595 | X40: 199.978 | Y40: =IF(AND(ISNUMBER(O40),ISNUMBER(S40),S40<>0),O40/S40-1,"") -> 0.10270678 | Z40: 0.11558271 | AA40: =IF(AND(ISNUMBER(O40),ISNUMBER(P40),P40<>0),O40/P40-1,"") -> 0.10369213 | AB40: =IF(AND(ISNUMBER(P40),ISNUMBER(Q40),Q40<>0),P40/Q40-1,"") -> 0.10663205 | AC40: =IF(AND(ISNUMBER(Q40),ISNUMBER(R40),R40<>0),Q40/R40-1,"") -> -0.10954617 | AD40: =IF(AND(ISNUMBER(R40),ISNUMBER(S40),S40<>0),R40/S40-1,"") -> 0.013905428 | AE40: 221.52 | AF40: 323.26001 | AG40: =IF(AND(ISNUMBER(AE40),ISNUMBER(AF40)),AF40/AE40-1,"") -> 0.45928134 | AH40: 32.798786 | AI40: 24.98525 | AJ40: These trends position the Company to deliver third quarter fiscal 2026 sales in the range of $760 to $790 million. | AK40: 8-K 보기
...

Sheet 섹터 요약
A1: 섹터(GICS) | B1: 가이던스 비교 가능 기업 수 | C1: 크게 상회 기업 수 | D1: 크게 상회 비율 | E1: 가이던스 대비 중앙값 (섹터 전체) | F1: 크게 상회 기업의 1년 주가수익률 중앙값 | G1: 크게 상회 기업
A2: Communication | B2: =COUNTIF('전체 가이던스 비교'!$C$2:$C$152,A2) -> 8 | C2: =COUNTIF('가이던스 상회 기업'!$C$2:$C$46,A2) -> 1 | D2: =IF(B2>0,C2/B2,"") -> 0.125 | E2: {=IFERROR(MEDIAN(IF(('전체 가이던스 비교'!$C$2:$C$152=A2)*ISNUMBER('전체 가이던스 비교'!$J$2:$J$152),'전체 가이던스 비교'!$J$2:$J$152)),"")} -> 0.009824586 | F2: {=IFERROR(MEDIAN(IF(('가이던스 상회 기업'!$C$2:$C$46=A2)*ISNUMBER('가이던스 상회 기업'!$AG$2:$AG$46),'가이던스 상회 기업'!$AG$2:$AG$46)),"")} -> -0.34384532 | G2: RDDT
A3: Consumer Discretionary | B3: =COUNTIF('전체 가이던스 비교'!$C$2:$C$152,A3) -> 6 | C3: =COUNTIF('가이던스 상회 기업'!$C$2:$C$46,A3) -> 1 | D3: =IF(B3>0,C3/B3,"") -> 0.16666667 | E3: {=IFERROR(MEDIAN(IF(('전체 가이던스 비교'!$C$2:$C$152=A3)*ISNUMBER('전체 가이던스 비교'!$J$2:$J$152),'전체 가이던스 비교'!$J$2:$J$152)),"")} -> 0.0013827349 | F3: {=IFERROR(MEDIAN(IF(('가이던스 상회 기업'!$C$2:$C$46=A3)*ISNUMBER('가이던스 상회 기업'!$AG$2:$AG$46),'가이던스 상회 기업'!$AG$2:$AG$46)),"")} -> 0.46572636 | G3: FIVE
A4: Consumer Staples | B4: =COUNTIF('전체 가이던스 비교'!$C$2:$C$152,A4) -> 2 | C4: =COUNTIF('가이던스 상회 기업'!$C$2:$C$46,A4) -> 0 | D4: =IF(B4>0,C4/B4,"") -> 0 | E4: {=IFERROR(MEDIAN(IF(('전체 가이던스 비교'!$C$2:$C$152=A4)*ISNUMBER('전체 가이던스 비교'!$J$2:$J$152),'전체 가이던스 비교'!$J$2:$J$152)),"")} -> 0.0074457169 | F4: {=IFERROR(MEDIAN(IF(('가이던스 상회 기업'!$C$2:$C$46=A4)*ISNUMBER('가이던스 상회 기업'!$AG$2:$AG$46),'가이던스 상회 기업'!$AG$2:$AG$46)),"")}
A5: Energy | B5: =COUNTIF('전체 가이던스 비교'!$C$2:$C$152,A5) -> 3 | C5: =COUNTIF('가이던스 상회 기업'!$C$2:$C$46,A5) -> 0 | D5: =IF(B5>0,C5/B5,"") -> 0 | E5: {=IFERROR(MEDIAN(IF(('전체 가이던스 비교'!$C$2:$C$152=A5)*ISNUMBER('전체 가이던스 비교'!$J$2:$J$152),'전체 가이던스 비교'!$J$2:$J$152)),"")} -> 0.0043432432 | F5: {=IFERROR(MEDIAN(IF(('가이던스 상회 기업'!$C$2:$C$46=A5)*ISNUMBER('가이던스 상회 기업'!$AG$2:$AG$46),'가이던스 상회 기업'!$AG$2:$AG$46)),"")}
A6: Financials | B6: =COUNTIF('전체 가이던스 비교'!$C$2:$C$152,A6) -> 5 | C6: =COUNTIF('가이던스 상회 기업'!$C$2:$C$46,A6) -> 0 | D6: =IF(B6>0,C6/B6,"") -> 0 | E6: {=IFERROR(MEDIAN(IF(('전체 가이던스 비교'!$C$2:$C$152=A6)*ISNUMBER('전체 가이던스 비교'!$J$2:$J$152),'전체 가이던스 비교'!$J$2:$J$152)),"")} -> 0.022523745 | F6: {=IFERROR(MEDIAN(IF(('가이던스 상회 기업'!$C$2:$C$46=A6)*ISNUMBER('가이던스 상회 기업'!$AG$2:$AG$46),'가이던스 상회 기업'!$AG$2:$AG$46)),"")}
A7: Health Care | B7: =COUNTIF('전체 가이던스 비교'!$C$2:$C$152,A7) -> 6 | C7: =COUNTIF('가이던스 상회 기업'!$C$2:$C$46,A7) -> 0 | D7: =IF(B7>0,C7/B7,"") -> 0 | E7: {=IFERROR(MEDIAN(IF(('전체 가이던스 비교'!$C$2:$C$152=A7)*ISNUMBER('전체 가이던스 비교'!$J$2:$J$152),'전체 가이던스 비교'!$J$2:$J$152)),"")} -> 0.030428997 | F7: {=IFERROR(MEDIAN(IF(('가이던스 상회 기업'!$C$2:$C$46=A7)*ISNUMBER('가이던스 상회 기업'!$AG$2:$AG$46),'가이던스 상회 기업'!$AG$2:$AG$46)),"")}
A8: Industrials | B8: =COUNTIF('전체 가이던스 비교'!$C$2:$C$152,A8) -> 16 | C8: =COUNTIF('가이던스 상회 기업'!$C$2:$C$46,A8) -> 6 | D8: =IF(B8>0,C8/B8,"") -> 0.375 | E8: {=IFERROR(MEDIAN(IF(('전체 가이던스 비교'!$C$2:$C$152=A8)*ISNUMBER('전체 가이던스 비교'!$J$2:$J$152),'전체 가이던스 비교'!$J$2:$J$152)),"")} -> 0.036052448 | F8: {=IFERROR(MEDIAN(IF(('가이던스 상회 기업'!$C$2:$C$46=A8)*ISNUMBER('가이던스 상회 기업'!$AG$2:$AG$46),'가이던스 상회 기업'!$AG$2:$AG$46)),"")} -> 0.01998697 | G8: KTOS, FPS, PL, TREX, NDSN, MIDD
A9: Information Technology | B9: =COUNTIF('전체 가이던스 비교'!$C$2:$C$152,A9) -> 99 | C9: =COUNTIF('가이던스 상회 기업'!$C$2:$C$46,A9) -> 35 | D9: =IF(B9>0,C9/B9,"") -> 0.35353535 | E9: {=IFERROR(MEDIAN(IF(('전체 가이던스 비교'!$C$2:$C$152=A9)*ISNUMBER('전체 가이던스 비교'!$J$2:$J$152),'전체 가이던스 비교'!$J$2:$J$152)),"")} -> 0.031256154 | F9: {=IFERROR(MEDIAN(IF(('가이던스 상회 기업'!$C$2:$C$46=A9)*ISNUMBER('가이던스 상회 기업'!$AG$2:$AG$46),'가이던스 상회 기업'!$AG$2:$AG$46)),"")} -> 0.63398644 | G9: MU, SNX, INTC, SNDK, AVT, NTAP, TER, MPWR, FTNT, LSCC, ANET, RBRK, P, FORM, PLTR, APH, U, TEAM, ENTG, AEIS, KEYS, FIG, ARW, NVDA, FLEX, TTMI, ONTO, DELL, LFUS, MDB, AMKR, INGM, IOT, TWLO, TXN
A10: Materials | B10: =COUNTIF('전체 가이던스 비교'!$C$2:$C$152,A10) -> 2 | C10: =COUNTIF('가이던스 상회 기업'!$C$2:$C$46,A10) -> 2 | D10: =IF(B10>0,C10/B10,"") -> 1 | E10: {=IFERROR(MEDIAN(IF(('전체 가이던스 비교'!$C$2:$C$152=A10)*ISNUMBER('전체 가이던스 비교'!$J$2:$J$152),'전체 가이던스 비교'!$J$2:$J$152)),"")} -> 0.083766126 | F10: {=IFERROR(MEDIAN(IF(('가이던스 상회 기업'!$C$2:$C$46=A10)*ISNUMBER('가이던스 상회 기업'!$AG$2:$AG$46),'가이던스 상회 기업'!$AG$2:$AG$46)),"")} -> 0.40398064 | G10: JHX, SOLS
A11: Real Estate | B11: =COUNTIF('전체 가이던스 비교'!$C$2:$C$152,A11) -> 4 | C11: =COUNTIF('가이던스 상회 기업'!$C$2:$C$46,A11) -> 0 | D11: =IF(B11>0,C11/B11,"") -> 0 | E11: {=IFERROR(MEDIAN(IF(('전체 가이던스 비교'!$C$2:$C$152=A11)*ISNUMBER('전체 가이던스 비교'!$J$2:$J$152),'전체 가이던스 비교'!$J$2:$J$152)),"")} -> 0.0054824246 | F11: {=IFERROR(MEDIAN(IF(('가이던스 상회 기업'!$C$2:$C$46=A11)*ISNUMBER('가이던스 상회 기업'!$AG$2:$AG$46),'가이던스 상회 기업'!$AG$2:$AG$46)),"")}
A12: 합계 | B12: =SUM(B2:B11) -> 151 | C12: =SUM(C2:C11) -> 45 | D12: =IF(B12>0,C12/B12,"") -> 0.29801325

Sheet 전체 가이던스 비교
A1: 기업명 | B1: 티커 | C1: 섹터(GICS) | D1: Q0 종료일 | E1: 가이던스 하단 (백만$) | F1: 가이던스 상단 (백만$) | G1: 가이던스 중앙값 (백만$) | H1: Q0 실제 매출 (백만$) | I1: 가이던스 형태 | J1: 가이던스 중앙값 대비 | K1: 가이던스 상단 대비 | L1: 크게 상회 | M1: 매출성장률(YoY) | N1: 가이던스 근거 문장 | O1: SEC 공시 | P1: 근거 문장 수동 검토
A2: Micron Technology | B2: MU | C2: Information Technology | D2: 2026-05-31 | E2: 32750 | F2: 34250 | G2: 33500 | H2: 41456 | I2: ±금액 | J2: =H2/G2-1 -> 0.23749254 | K2: =H2/F2-1 -> 0.21039416 | L2: =IF(AND(J2>=0.05,K2>0),"예","") -> 예 | M2: 3.4571551 | N2: Revenue $33.5 billion ± $750 million $33.5 billion ± $750 million | O2: 8-K 보기 | P2: 검토 완료
A3: TD SYNNEX Corporation | B3: SNX | C3: Information Technology | D3: 2026-05-31 | E3: 16100 | F3: 16900 | G3: 16500 | H3: 19574.813 | I3: 범위 | J3: =H3/G3-1 -> 0.1863523 | K3: =H3/F3-1 -> 0.15827296 | L3: =IF(AND(J3>=0.05,K3>0),"예","") -> 예 | M3: 0.30967486 | N3: Revenue $16.1 - $16.9 billion | O3: 8-K 보기 | P3: 검토 완료
A4: Kratos Defense & Security Solut | B4: KTOS | C4: Industrials | D4: 2026-06-30 | E4: 400 | F4: 410 | G4: 405 | H4: 458.8 | I4: 범위 | J4: =H4/G4-1 -> 0.13283951 | K4: =H4/F4-1 -> 0.11902439 | L4: =IF(AND(J4>=0.05,K4>0),"예","") -> 예 | M4: 0.30526316 | N4: Revenues $400 - $410 $1,700 - $1,760 | O4: 8-K 보기 | P4: 검토 완료
A5: Intel | B5: INTC | C5: Information Technology | D5: 2026-06-30 | E5: 13800 | F5: 14800 | G5: 14300 | H5: 16128 | I5: 범위 | J5: =H5/G5-1 -> 0.12783217 | K5: =H5/F5-1 -> 0.08972973 | L5: =IF(AND(J5>=0.05,K5>0),"예","") -> 예 | M5: 0.25421884 | N5: ▪ Forecasting second-quarter 2026 revenue of $13.8 billion to $14.8 billion; expecting second-quarter EPS attributable to Intel o f $0.08 and non-GAAP EPS attributable to Intel of $0.20. | O5: 8-K 보기 | P5: 검토 완료
A6: Sandisk | B6: SNDK | C6: Information Technology | D6: 2026-06-30 | E6: 7750 | F6: 8250 | G6: 8000 | H6: 8965 | I6: 범위 | J6: =H6/G6-1 -> 0.120625 | K6: =H6/F6-1 -> 0.086666667 | L6: =IF(AND(J6>=0.05,K6>0),"예","") -> 예 | M6: 3.715939 | N6: • Expect fourth quarter revenue to be in the range of $7.75 billion to $8.25 billion, with expected Non-GAAP diluted net income per share to be in the range of $30.00 to $33.00. | O6: 8-K 보기 | P6: 검토 완료
A7: Forgent Power Solutions, Inc. | B7: FPS | C7: Industrials | D7: 2026-06-30 | E7: 392 | F7: 432 | G7: 412 | H7: 461.672 | I7: 범위 | J7: =H7/G7-1 -> 0.12056311 | K7: =H7/F7-1 -> 0.068685185 | L7: =IF(AND(J7>=0.05,K7>0),"예","") -> 예 | M7: 0.94295767 | N7: Revenues $392 - $432 $1,350 - $1,390 | O7: 8-K 보기 | P7: 검토 완료
A8: Reddit | B8: RDDT | C8: Communication | D8: 2026-06-30 | E8: 715 | F8: 725 | G8: 720 | H8: 804.905 | I8: 범위 | J8: =H8/G8-1 -> 0.11792361 | K8: =H8/F8-1 -> 0.11021379 | L8: =IF(AND(J8>=0.05,K8>0),"예","") -> 예 | M8: 0.61101181 | N8: • Revenue in the range of $715 million to $725 million | O8: 8-K 보기 | P8: 검토 완료
A9: Avnet, Inc. | B9: AVT | C9: Information Technology | D9: 2026-06-30 | E9: 7300 | F9: 7600 | G9: 7450 | H9: 8295.377 | I9: 범위 | J9: =H9/G9-1 -> 0.11347342 | K9: =H9/F9-1 -> 0.091496974 | L9: =IF(AND(J9>=0.05,K9>0),"예","") -> 예 | M9: 0.47662508 | N9: Sales ​ $7.30B – $7.60B | O9: 8-K 보기 | P9: 검토 완료
A10: Planet Labs PBC | B10: PL | C10: Industrials | D10: 2026-07-31 | E10: 102 | F10: 107 | G10: 104.5 | H10: 116.052 | I10: 범위 | J10: =H10/G10-1 -> 0.11054545 | K10: =H10/F10-1 -> 0.084598131 | L10: =IF(AND(J10>=0.05,K10>0),"예","") -> 예 | M10: 0.58139155 | N10: For the second quarter of fiscal year 2027, ending July 31, 2026, Planet expects revenue to be in the range of approximately $102 million to $107 million. | O10: 8-K 보기 | P10: 검토 완료
A11: NetApp | B11: NTAP | C11: Information Technology | D11: 2026-07-31 | E11: 1750 | F11: 1900 | G11: 1825 | H11: 2025 | I11: 범위 | J11: =H11/G11-1 -> 0.10958904 | K11: =H11/F11-1 -> 0.065789474 | L11: =IF(AND(J11>=0.05,K11>0),"예","") -> 예 | M11: 0.29890956 | N11: Net revenues are expected to be in the range of: $1.750 billion - $1.900 billion | O11: 8-K 보기 | P11: 검토 완료
A12: Teradyne | B12: TER | C12: Information Technology | D12: 2026-06-30 | E12: 1150 | F12: 1250 | G12: 1200 | H12: 1328.99 | I12: 범위 | J12: =H12/G12-1 -> 0.10749167 | K12: =H12/F12-1 -> 0.063192 | L12: =IF(AND(J12>=0.05,K12>0),"예","") -> 예 | M12: 1.0389631 | N12: Guidance for the second quarter of 2026 is revenue of $1,150 million to $1,250 million, with GAAP net income of $1.83 to $2.12 per diluted share and non-GAAP net income of $1.86 to $2.15 per diluted share. | O12: 8-K 보기 | P12: 검토 완료
A13: James Hardie Industries plc. | B13: JHX | C13: Materials | D13: 2026-06-30 | E13: 1320 | F13: 1350 | G13: 1335 | H13: 1474.6 | I13: 범위 | J13: =H13/G13-1 -> 0.10456929 | K13: =H13/F13-1 -> 0.092296296 | L13: =IF(AND(J13>=0.05,K13>0),"예","") -> 예 | M13: 0.63862651 | N13: • Total Net Sales: $1.32 to $1.35 billion | O13: 8-K 보기 | P13: 검토 완료
... A46: Texas Instruments | B46: TXN | C46: Information Technology | D46: 2026-06-30 | E46: 5000 | F46: 5400 | G46: 5200 | H46: 5463 | I46: 범위 | J46: =H46/G46-1 -> 0.050576923 | K46: =H46/F46-1 -> 0.011666667 | L46: =IF(AND(J46>=0.05,K46>0),"예","") -> 예 | M46: 0.22819245 | N46: • "TI's second quarter outlook is for revenue in the range of $5.00 billion to $5.40 billion and earnings per share between $1.77 and $2.05." | O46: 8-K 보기 | P46: 검토 완료
A47: CHIME FINANCIAL | B47: CHYM | C47: Financials | D47: 2026-06-30 | E47: 633 | F47: 643 | G47: 638 | H47: 669.768 | I47: 범위 | J47: =H47/G47-1 -> 0.049793103 | K47: =H47/F47-1 -> 0.04162986 | L47: =IF(AND(J47>=0.05,K47>0),"예","") | M47: 0.26814213 | N47: • Revenue between $633 million to $643 million, resulting in year-over-year revenue growth between 20% and 22%. | O47: 8-K 보기
A48: GITLAB | B48: GTLB | C48: Information Technology | D48: 2026-07-31 | E48: 272 | F48: 274 | G48: 273 | H48: 286.254 | I48: 범위 | J48: =H48/G48-1 -> 0.048549451 | K48: =H48/F48-1 -> 0.044722628 | L48: =IF(AND(J48>=0.05,K48>0),"예","") | M48: 0.2131463 | N48: Revenue $272 - $274 $1,112 - $1,118 | O48: 8-K 보기
A49: CLOUDFLARE | B49: NET | C49: Information Technology | D49: 2026-06-30 | E49: 664 | F49: 665 | G49: 664.5 | H49: 696.061 | I49: 범위 | J49: =H49/G49-1 -> 0.047495862 | K49: =H49/F49-1 -> 0.046708271 | L49: =IF(AND(J49>=0.05,K49>0),"예","") | M49: 0.3586556 | N49: • Total revenue of $664.0 to $665.0 million | O49: 8-K 보기
A50: eBay Inc. | B50: EBAY | C50: Consumer Discretionary | D50: 2026-06-30 | E50: 2970 | F50: 3030 | G50: 3000 | H50: 3134 | I50: 범위 | J50: =H50/G50-1 -> 0.044666667 | K50: =H50/F50-1 -> 0.034323432 | L50: =IF(AND(J50>=0.05,K50>0),"예","") | M50: 0.14798535 | N50: Net revenues $2.97 - $3.03 | O50: 8-K 보기
A51: KBR INC | B51: KBR | C51: Industrials | D51: 2026-06-30 | E51: 1900 | F51: 1900 | G51: 1900 | H51: 1984 | I51: 단일값 | J51: =H51/G51-1 -> 0.044210526 | K51: =H51/F51-1 -> 0.044210526 | L51: =IF(AND(J51>=0.05,K51>0),"예","") | M51: 0.016393443 | N51: • Revenues of $1.9 billion, down 5% due to expected EUCOM contingency runoff | O51: 8-K 보기
A52: Datadog | B52: DDOG | C52: Information Technology | D52: 2026-06-30 | E52: 1070 | F52: 1080 | G52: 1075 | H52: 1121.454 | I52: 범위 | J52: =H52/G52-1 -> 0.043213023 | K52: =H52/F52-1 -> 0.038383333 | L52: =IF(AND(J52>=0.05,K52>0),"예","") | M52: 0.35644443 | N52: ◦ Revenue between $1.07 billion and $1.08 billion. | O52: 8-K 보기
A53: SEMTECH | B53: SMTC | C53: Information Technology | D53: 2026-07-31 | E53: 323 | F53: 333 | G53: 328 | H53: 341.871 | I53: ±금액 | J53: =H53/G53-1 -> 0.042289634 | K53: =H53/F53-1 -> 0.02663964 | L53: =IF(AND(J53>=0.05,K53>0),"예","") | M53: 0.32719565 | N53: Net sales $ 328.0 +/- $5.0 | O53: 8-K 보기
A54: ELANCO ANIMAL HEALTH | B54: ELAN | C54: Health Care | D54: 2026-06-30 | E54: 1300 | F54: 1325 | G54: 1312.5 | H54: 1368 | I54: 범위 | J54: =H54/G54-1 -> 0.042285714 | K54: =H54/F54-1 -> 0.03245283 | L54: =IF(AND(J54>=0.05,K54>0),"예","") | M54: 0.10233683 | N54: Revenue (1) $1,300 to $1,325 | O54: 8-K 보기
A55: F5, Inc. | B55: FFIV | C55: Information Technology | D55: 2026-06-30 | E55: 820 | F55: 840 | G55: 830 | H55: 865.077 | I55: 범위 | J55: =H55/G55-1 -> 0.042261446 | K55: =H55/F55-1 -> 0.029853571 | L55: =IF(AND(J55>=0.05,K55>0),"예","") | M55: 0.10854723 | N55: For the third quarter of fiscal year 2026, F5 is guiding to revenue in the range of $820 million to $840 million, with non-GAAP earnings in the range of $3.91 to $4.03 per diluted share. | O55: 8-K 보기
A56: ROKU | B56: ROKU | C56: Communication | D56: 2026-06-30 | E56: 1300 | F56: 1300 | G56: 1300 | H56: 1354.69 | I56: 단일값 | J56: =H56/G56-1 -> 0.042069231 | K56: =H56/F56-1 -> 0.042069231 | L56: =IF(AND(J56>=0.05,K56>0),"예","") | M56: 0.21930123 | N56: We expect this to result in Total net revenue of $1.3 billion, up nearly 17% YoY, with Total gross profit of $580 million and Adjusted EBITDA of $170 million. | O56: 8-K 보기
A57: NOV | B57: NOV | C57: Energy | D57: 2026-06-30 | E57: 2050 | F57: 2050 | G57: 2050 | H57: 2134 | I57: 단일값 | J57: =H57/G57-1 -> 0.04097561 | K57: =H57/F57-1 -> 0.04097561 | L57: =IF(AND(J57>=0.05,K57>0),"예","") | M57: -0.024680073 | N57: On a consolidated basis, the Company currently expects to report revenues of $2.05 billion, operating profit of $47 million, and Adjusted EBITDA* of $177 million. | O57: 8-K 보기
A58: MKS | B58: MKSI | C58: Information Technology | D58: 2026-06-30 | E58: 1160 | F58: 1240 | G58: 1200 | H58: 1248 | I58: ±금액 | J58: =H58/G58-1 -> 0.04 | K58: =H58/F58-1 -> 0.0064516129 | L58: =IF(AND(J58>=0.05,K58>0),"예","") | M58: 0.28263104 | N58: • Revenue of $1,200 million, plus or minus $40 million | O58: 8-K 보기
... A152: T-Mobile US | B152: TMUS | C152: Communication | D152: 2026-06-30 | E152: 37100 | F152: 37500 | G152: 37300 | H152: 22791 | I152: 범위 | J152: =H152/G152-1 -> -0.38898123 | K152: =H152/F152-1 -> -0.39224 | L152: =IF(AND(J152>=0.05,K152>0),"예","") | M152: 0.07850653 | N152: • Core Adjusted EBITDA, which is Adjusted EBITDA less lease revenues, is expected to be between $37.1 billion and $37.5 billion, an increase at the midpoint from prior guidance of $37.0 billion to $37.5 billion. | O152: 8-K 보기

Sheet 메모
A1: 작성 기준일 | B1: 2026-09-25 23:04 KST
A2: 대상 | B2: Russell 1000 (iShares IWB 보유종목, 1012개 기업, 동일 기업 복수 주식 클래스 제외)
A3: 최근 분기(Q0) | B3: 각 기업이 가장 최근에 실적을 발표한 분기 (Yahoo Finance 분기 손익계산서 기준, 값이 빈 최신 분기는 제외)
A4: 회사 가이던스 | B4: Q0 직전 분기 실적 발표문(SEC 8-K Item 2.02, Exhibit 99)에 회사가 제시한 'Q0 매출 전망'. 분기 중 수정 발표가 있으면 가장 최근 것. 규칙 기반 문장 추출 → 근거 문장 열에 원문 표기
A5: 가이던스 비교 가능 | B5: 151개 기업 (분기 매출 가이던스를 숫자로 제시한 기업). 나머지는 가이던스 미제공·연간 가이던스만 제공·EPS만 제공·보도자료 외(컨퍼런스콜)에서만 제공
A6: '크게 상회' 기준 | B6: Q0 실제 매출이 가이던스 중앙값보다 5% 이상 높고, 가이던스 상단도 넘은 경우
A7: 가이던스 형태 | B7: 범위(하단~상단), ±금액, ±%, 단일값(approximately), 성장률(전년 동기 매출 × (1+가이던스 성장률)로 환산)
A8: EPS 서프라이즈 | B8: Yahoo Finance: 최근 분기 실제 EPS vs 애널리스트 컨센서스 (회사 가이던스가 아닌 참고 지표)
A9: 주가수익률 | B9: 2025-09-25 종가 → 2026-09-24 종가 (Yahoo, 분할 조정·배당 제외)
A10: PER / Forward PER | B10: Yahoo Finance trailingPE / forwardPE (수집 시점 주가 기준). 최근 12개월 적자 또는 향후 12개월 적자 예상이면 빈칸
A11: 1년 주가수익률 빈칸 | B11: 시작일 이후 상장·분사한 종목 (상장 1년 미만)
A12: 매출·영업이익 | B12: Yahoo Finance quarterly_income_stmt, 백만 달러. 영업이익 YoY 규칙: Q-4 ≤ 0 → 흑자전환/N/M, Q-4>0 & Q0<0 → 적자전환
A13: 주의 | B13: 가이던스와 실제 매출의 기준(GAAP/비GAAP, 환율·인수 효과 등)이 다를 수 있음. 인수합병으로 매출이 늘어난 경우 가이던스에 반영되지 않았을 수 있으니 근거 문장을 확인할 것. 투자 판단의 근거가 아닌 스크리닝 결과임
