Workbook

Sheet 실적
A1: 기업명 | B1: 티커 | C1: 최근 분기 종료일 | D1: 매출 Q0 (백만$) | E1: 매출 Q-1 (백만$) | F1: 매출 Q-2 (백만$) | G1: 매출 Q-3 (백만$) | H1: 매출 Q-4 (백만$) | I1: 영업이익 Q0 (백만$) | J1: 영업이익 Q-1 (백만$) | K1: 영업이익 Q-2 (백만$) | L1: 영업이익 Q-3 (백만$) | M1: 영업이익 Q-4 (백만$) | N1: 매출성장률(YoY) | O1: 영업이익성장률(YoY) | P1: 매출 QoQ(Q0) | Q1: 매출 QoQ(Q-1) | R1: 매출 QoQ(Q-2) | S1: 매출 QoQ(Q-3) | T1: 선정 기준 | U1: 주요 사업 | V1: GICS 섹터 | W1: 주가 2025-09-24 ($) | X1: 주가 2026-09-23 ($) | Y1: 1년 주가수익률 | Z1: 1년 총수익률(배당 포함) | AA1: 1년 전 매출성장률(YoY, 2025-09-24 시점) | AB1: 1년 전 선정 기준 (2025-09-24 시점) | AC1: 매출 YoY 변화(%p, 현재-1년 전)
A2: CDW Corporation | B2: CDW | C2: 2026-06-30 | D2: 6572.2 | E2: 5679.8 | F2: 5511 | G2: 5737.4 | H2: 5976.6 | I2: 428.6 | J2: 376 | K2: 430.7 | L2: 443.3 | M2: 420.2 | N2: 0.099655322 | O2: 0.019990481 | P2: 0.15711821 | Q2: 0.03062965 | R2: -0.039460383 | S2: -0.040022755 | T2: QoQ 가속 + 최근 QoQ≥10% | U2: 기업·공공기관 대상 IT 하드웨어·소프트웨어 유통 및 솔루션 | V2: Information Technology | W2: 160.47 | X2: 146.16 | Y2: =IF(AND(ISNUMBER(W2),ISNUMBER(X2)),X2/W2-1,"") -> -0.089175547 | Z2: -0.070628869 | AA2: 0.10200243 | AB2: 최근 QoQ≥10% | AC2: =IF(AND(ISNUMBER(N2),ISNUMBER(AA2)),N2-AA2,"") -> -0.0023471115
A3: Applied Materials | B3: AMAT | C3: 2026-07-31 | D3: 9115 | E3: 7910 | F3: 7012 | G3: 6800 | H3: 7302 | I3: 3075 | J3: 2523 | K3: 2096 | L3: 1893 | M3: 2233 | N3: 0.24828814 | O3: 0.3770712 | P3: 0.15233881 | Q3: 0.12806617 | R3: 0.031176471 | S3: -0.068748288 | T3: QoQ 가속 + 최근 QoQ≥10% | U3: 반도체·디스플레이 제조 장비 | V3: Information Technology | W3: 201.44 | X3: 474.38 | Y3: =IF(AND(ISNUMBER(W3),ISNUMBER(X3)),X3/W3-1,"") -> 1.3549444 | Z3: 1.3679697 | AA3: 0.077308941 | AC3: =IF(AND(ISNUMBER(N3),ISNUMBER(AA3)),N3-AA3,"") -> 0.1709792
A4: Home Depot (The) | B4: HD | C4: 2026-07-31 | D4: 47861 | E4: 41765 | F4: 38198 | G4: 41352 | H4: 45277 | I4: 6839 | J4: 4981 | K4: 3849 | L4: 5353 | M4: 6555 | N4: 0.057070919 | O4: 0.043325706 | P4: 0.14595954 | Q4: 0.093381852 | R4: -0.076272006 | S4: -0.086688606 | T4: QoQ 가속 + 최근 QoQ≥10% | U4: 주택개량 자재·용품 소매 | V4: Consumer Discretionary | W4: 409.77 | X4: 296.72 | Y4: =IF(AND(ISNUMBER(W4),ISNUMBER(X4)),X4/W4-1,"") -> -0.27588647 | Z4: -0.25538046 | AA4: 0.048685582 | AB4: QoQ 가속 + 최근 QoQ≥10% | AC4: =IF(AND(ISNUMBER(N4),ISNUMBER(AA4)),N4-AA4,"") -> 0.0083853371
A5: Eaton Corporation | B5: ETN | C5: 2026-06-30 | D5: 8531 | E5: 7451 | F5: 7055 | G5: 6988 | H5: 7028 | I5: 1392 | J5: 1172 | K5: 1386 | L5: 1367 | M5: 1256 | N5: 0.21385885 | O5: 0.10828025 | P5: 0.14494699 | Q5: 0.056130404 | R5: 0.0095878649 | S5: -0.0056915196 | T5: QoQ 가속 + 최근 QoQ≥10% | U5: 전력관리 장비 (데이터센터·전기·항공) | V5: Industrials | W5: 372.21 | X5: 438.76 | Y5: =IF(AND(ISNUMBER(W5),ISNUMBER(X5)),X5/W5-1,"") -> 0.17879692 | Z5: 0.19193964 | AA5: 0.10677165 | AB5: 최근 QoQ≥10% | AC5: =IF(AND(ISNUMBER(N5),ISNUMBER(AA5)),N5-AA5,"") -> 0.1070872
A6: Cboe Global Markets | B6: CBOE | C6: 2026-06-30 | D6: 1442.8 | E6: 1272.8 | F6: 1204 | G6: 1141.7 | H6: 1173.5 | I6: 476 | J6: 505.6 | K6: 428.8 | L6: 375 | M6: 356.2 | N6: 0.22948445 | O6: 0.33632791 | P6: 0.1335638 | Q6: 0.057142857 | R6: 0.05456775 | S6: -0.027098424 | T6: QoQ 가속 + 최근 QoQ≥10% | U6: 옵션·주식·선물 거래소 운영 | V6: Financials | W6: 243.19 | X6: 268.87 | Y6: =IF(AND(ISNUMBER(W6),ISNUMBER(X6)),X6/W6-1,"") -> 0.10559645 | Z6: 0.11373477 | AA6: 0.20482546 | AC6: =IF(AND(ISNUMBER(N6),ISNUMBER(AA6)),N6-AA6,"") -> 0.024658986
A7: Marvell Technology | B7: MRVL | C7: 2026-07-31 | D7: 2739.3 | E7: 2417.8 | F7: 2218.7 | G7: 2074.5 | H7: 2006.1 | I7: 456.9 | J7: 350.1 | K7: 413.9 | L7: 367.4 | M7: 298.8 | N7: 0.36548527 | O7: 0.52911647 | P7: 0.13297212 | Q7: 0.089737234 | R7: 0.069510725 | S7: 0.034096007 | T7: QoQ 가속 + 최근 QoQ≥10% | U7: 데이터센터용 맞춤형 AI 칩·광통신·네트워크 반도체 | V7: Information Technology | W7: 80.09 | X7: 260.9 | Y7: =IF(AND(ISNUMBER(W7),ISNUMBER(X7)),X7/W7-1,"") -> 2.2575852 | Z7: 2.2645257 | AA7: 0.57600754 | AC7: =IF(AND(ISNUMBER(N7),ISNUMBER(AA7)),N7-AA7,"") -> -0.21052227
A8: Coherent Corp. | B8: COHR | C8: 2026-06-30 | D8: 2045.533 | E8: 1805.641 | F8: 1685.629 | G8: 1581.378 | H8: 1529.436 | I8: 304.338 | J8: 226.321 | K8: 198.624 | L8: 172.239 | M8: 144.978 | N8: 0.33744269 | O8: 1.0992013 | P8: 0.13285697 | Q8: 0.071197161 | R8: 0.06592415 | S8: 0.033961539 | T8: QoQ 가속 + 최근 QoQ≥10% | U8: 레이저·광트랜시버 등 광학·광전자 부품 | V8: Information Technology | W8: 106.52 | X8: 300.6 | Y8: =IF(AND(ISNUMBER(W8),ISNUMBER(X8)),X8/W8-1,"") -> 1.8220053 | Z8: 1.8220054 | AA8: 0.16363376 | AC8: =IF(AND(ISNUMBER(N8),ISNUMBER(AA8)),N8-AA8,"") -> 0.17380893
A9: Lowe's | B9: LOW | C9: 2026-07-31 | D9: 25956 | E9: 23078 | F9: 20585 | G9: 20813 | H9: 23959 | I9: 3549 | J9: 2554 | K9: 1708 | L9: 2481 | M9: 3469 | N9: 0.083350724 | O9: 0.023061401 | P9: 0.12470751 | Q9: 0.1211076 | R9: -0.010954692 | S9: -0.13130765 | T9: QoQ 가속 + 최근 QoQ≥10% | U9: 주택개량 자재·용품 소매 | V9: Consumer Discretionary | W9: 257.33 | X9: 191.36 | Y9: =IF(AND(ISNUMBER(W9),ISNUMBER(X9)),X9/W9-1,"") -> -0.25636342 | Z9: -0.2410864 | AA9: 0.015814466 | AB9: QoQ 가속 + 최근 QoQ≥10% | AC9: =IF(AND(ISNUMBER(N9),ISNUMBER(AA9)),N9-AA9,"") -> 0.067536258
A10: Arista Networks | B10: ANET | C10: 2026-06-30 | D10: 3035.7 | E10: 2709 | F10: 2487.8 | G10: 2308.3 | H10: 2204.8 | I10: 1378 | J10: 1157.8 | K10: 1032.9 | L10: 978.2 | M10: 986.2 | N10: 0.37685958 | O10: 0.3972825 | P10: 0.12059801 | Q10: 0.0889139 | R10: 0.077762856 | S10: 0.046943033 | T10: QoQ 가속 + 최근 QoQ≥10% | U10: 데이터센터·AI 클러스터용 고속 네트워크 스위치 | V10: Information Technology | W10: 142.64 | X10: 203.47 | Y10: =IF(AND(ISNUMBER(W10),ISNUMBER(X10)),X10/W10-1,"") -> 0.42645822 | Z10: 0.42645823 | AA10: 0.30430667 | AC10: =IF(AND(ISNUMBER(N10),ISNUMBER(AA10)),N10-AA10,"") -> 0.072552906
A11: Darden Restaurants | B11: DRI | C11: 2026-05-31 | D11: 3718.8 | E11: 3345.3 | F11: 3102.1 | G11: 3044.7 | H11: 3271.7 | I11: 537.6 | J11: 440.3 | K11: 325.6 | L11: 303.1 | M11: 455.7 | N11: 0.13665678 | O11: 0.1797235 | P11: 0.11164918 | Q11: 0.078398504 | R11: 0.018852432 | S11: -0.06938289 | T11: QoQ 가속 + 최근 QoQ≥10% | U11: 올리브가든 등 캐주얼 다이닝 레스토랑 체인 | V11: Consumer Discretionary | W11: 186.61 | X11: 213.69 | Y11: =IF(AND(ISNUMBER(W11),ISNUMBER(X11)),X11/W11-1,"") -> 0.14511548 | Z11: 0.1814377 | AA11: 0.10631319 | AC11: =IF(AND(ISNUMBER(N11),ISNUMBER(AA11)),N11-AA11,"") -> 0.030343593
A12: Howmet Aerospace | B12: HWM | C12: 2026-06-30 | D12: 2547 | E12: 2313 | F12: 2168 | G12: 2089 | H12: 2053 | I12: 711 | J12: 660 | K12: 577 | L12: 542 | M12: 521 | N12: 0.24062348 | O12: 0.3646833 | P12: 0.10116732 | Q12: 0.066881919 | R12: 0.037817137 | S12: 0.017535314 | T12: QoQ 가속 + 최근 QoQ≥10% | U12: 항공기 엔진 부품·체결재 및 단조 휠 | V12: Industrials | W12: 190.22 | X12: 228.78 | Y12: =IF(AND(ISNUMBER(W12),ISNUMBER(X12)),X12/W12-1,"") -> 0.20271265 | Z12: 0.2052166 | AA12: 0.092021277 | AC12: =IF(AND(ISNUMBER(N12),ISNUMBER(AA12)),N12-AA12,"") -> 0.1486022
A13: Apollo Global Management | B13: APO | C13: 2026-06-30 | D13: 11153 | E13: 5057 | F13: 9864 | G13: 9823 | H13: 6814 | I13: 2850 | J13: 794 | K13: 2105 | L13: 3172 | M13: 1448 | N13: 0.63677722 | O13: 0.96823204 | P13: 1.2054578 | Q13: -0.48732766 | R13: 0.0041738776 | S13: 0.44159084 | T13: 최근 QoQ≥10% | U13: 사모신용·사모펀드 대체자산 운용 및 은퇴보험(Athene) | V13: Financials | W13: 137.16 | X13: 124.36 | Y13: =IF(AND(ISNUMBER(W13),ISNUMBER(X13)),X13/W13-1,"") -> -0.093321668 | Z13: -0.078318099 | AA13: 0.13226986 | AB13: 최근 QoQ≥10% | AC13: =IF(AND(ISNUMBER(N13),ISNUMBER(AA13)),N13-AA13,"") -> 0.50450737
A14: Live Nation Entertainment | B14: LYV | C14: 2026-06-30 | D14: 7666.858 | E14: 3793.029 | F14: 6313.505 | G14: 8499.143 | H14: 7006.641 | I14: 513.401 | J14: -376.538 | K14: -143.275 | L14: 777.6 | M14: 485.797 | N14: 0.094227319 | O14: 0.056822088 | P14: 1.0213022 | Q14: -0.39921977 | R14: -0.25715981 | S14: 0.21301248 | T14: 최근 QoQ≥10% | U14: 공연 기획·프로모션 및 티켓 판매(티켓마스터) | V14: Communication Services | W14: 162.08 | X14: 169.03 | Y14: =IF(AND(ISNUMBER(W14),ISNUMBER(X14)),X14/W14-1,"") -> 0.042880059 | Z14: 0.04288004 | AA14: 0.16323379 | AB14: 최근 QoQ≥10% | AC14: =IF(AND(ISNUMBER(N14),ISNUMBER(AA14)),N14-AA14,"") -> -0.069006467
A15: Devon Energy | B15: DVN | C15: 2026-06-30 | D15: 7417 | E15: 3807 | F15: 4121 | G15: 4331 | H15: 4284 | I15: 2543 | J15: 312 | K15: 841 | L15: 982 | M15: 981 | N15: 0.73132586 | O15: 1.5922528 | P15: 0.94825322 | Q15: -0.076195098 | R15: -0.048487647 | S15: 0.010971055 | T15: 최근 QoQ≥10% | U15: 미국 셰일 원유·천연가스 탐사·생산 | V15: Energy | W15: 35.21 | X15: 48.04 | Y15: =IF(AND(ISNUMBER(W15),ISNUMBER(X15)),X15/W15-1,"") -> 0.36438512 | Z15: 0.39916213 | AA15: 0.093694154 | AC15: =IF(AND(ISNUMBER(N15),ISNUMBER(AA15)),N15-AA15,"") -> 0.63763171
A16: Keurig Dr Pepper | B16: KDP | C16: 2026-06-30 | D16: 7309 | E16: 3976 | F16: 4499 | G16: 4306 | H16: 4163 | I16: 628 | J16: 756 | K16: 959 | L16: 995 | M16: 898 | N16: 0.75570502 | O16: -0.30066815 | P16: 0.83827968 | Q16: -0.11624806 | R16: 0.04482118 | S16: 0.034350228 | T16: 최근 QoQ≥10% | U16: 커피(큐리그)·음료 브랜드 제조 및 유통 | V16: Consumer Staples | W16: 26.25 | X16: 31.76 | Y16: =IF(AND(ISNUMBER(W16),ISNUMBER(X16)),X16/W16-1,"") -> 0.20990476 | Z16: 0.25063386 | AA16: 0.061448241 | AB16: 최근 QoQ≥10% | AC16: =IF(AND(ISNUMBER(N16),ISNUMBER(AA16)),N16-AA16,"") -> 0.69425678
A17: Micron Technology | B17: MU | C17: 2026-05-31 | D17: 41456 | E17: 23860 | F17: 13643 | G17: 11315 | H17: 9301 | I17: 33318 | J17: 16135 | K17: 6136 | L17: 3693 | M17: 2169 | N17: 3.4571551 | O17: 14.360996 | P17: 0.73746857 | Q17: 0.74888221 | R17: 0.20574459 | S17: 0.21653586 | T17: 최근 QoQ≥10% | U17: D램·낸드 메모리 반도체 제조 (AI 서버용 HBM 포함) | V17: Information Technology | W17: 161.71 | X17: 1071.88 | Y17: =IF(AND(ISNUMBER(W17),ISNUMBER(X17)),X17/W17-1,"") -> 5.6284089 | Z17: 5.6390471 | AA17: 0.36558508 | AB17: 최근 QoQ≥10% | AC17: =IF(AND(ISNUMBER(N17),ISNUMBER(AA17)),N17-AA17,"") -> 3.0915701
A18: Phillips 66 | B18: PSX | C18: 2026-06-30 | D18: 51004 | E18: 32540 | F18: 34108 | G18: 34515 | H18: 33323 | I18: 4280 | J18: 114 | K18: 1621 | L18: 965 | M18: 1190 | N18: 0.53059448 | O18: 2.5966387 | P18: 0.56742471 | Q18: -0.04597162 | R18: -0.011791975 | S18: 0.035771089 | T18: 최근 QoQ≥10% | U18: 석유 정제·화학·미드스트림·마케팅 | V18: Energy | W18: 136.59 | X18: 256.48 | Y18: =IF(AND(ISNUMBER(W18),ISNUMBER(X18)),X18/W18-1,"") -> 0.87773629 | Z18: 0.93334039 | AA18: -0.12604579 | AC18: =IF(AND(ISNUMBER(N18),ISNUMBER(AA18)),N18-AA18,"") -> 0.65664028
A19: Occidental Petroleum | B19: OXY | C19: 2026-06-30 | D19: 8065 | E19: 5230 | F19: 1752 | G19: 6624 | H19: 5258 | I19: 3665 | J19: 927 | K19: 117 | L19: 1174 | M19: 798 | N19: 0.53385318 | O19: 3.5927318 | P19: 0.54206501 | Q19: 1.9851598 | R19: -0.73550725 | S19: 0.2597946 | T19: 최근 QoQ≥10% | U19: 원유·가스 탐사·생산 및 화학(OxyChem) | V19: Energy | W19: 46.89 | X19: 57.36 | Y19: =IF(AND(ISNUMBER(W19),ISNUMBER(X19)),X19/W19-1,"") -> 0.22328855 | Z19: 0.24764654 | AA19: -0.059116914 | AC19: =IF(AND(ISNUMBER(N19),ISNUMBER(AA19)),N19-AA19,"") -> 0.59297009
A20: Marathon Petroleum | B20: MPC | C20: 2026-06-30 | D20: 51994 | E20: 34200 | F20: 32574 | G20: 34809 | H20: 33799 | I20: 6979 | J20: 1036 | K20: 1846 | L20: 1673 | M20: 1895 | N20: 0.53832954 | O20: 2.6828496 | P20: 0.5202924 | Q20: 0.049917112 | R20: -0.064207533 | S20: 0.029882541 | T20: 최근 QoQ≥10% | U20: 석유 정제·마케팅 및 미드스트림(MPLX) | V20: Energy | W20: 193.1 | X20: 388.38 | Y20: =IF(AND(ISNUMBER(W20),ISNUMBER(X20)),X20/W20-1,"") -> 1.0112895 | Z20: 1.0448839 | AA20: -0.10853511 | AB20: QoQ 가속 | AC20: =IF(AND(ISNUMBER(N20),ISNUMBER(AA20)),N20-AA20,"") -> 0.64686464
A21: Sandisk | B21: SNDK | C21: 2026-06-30 | D21: 8965 | E21: 5950 | F21: 3025 | G21: 2308 | H21: 1901 | I21: 7037 | J21: 4164 | K21: 1075 | L21: 192 | M21: 51 | N21: 3.715939 | O21: 136.98039 | P21: 0.50672269 | Q21: 0.96694215 | R21: 0.31065858 | S21: 0.21409784 | T21: 최근 QoQ≥10% | U21: 낸드 플래시 메모리·SSD 등 데이터 저장장치 제조 (WD에서 분사) | V21: Information Technology | W21: 99.83 | X21: 1816.5699 | Y21: =IF(AND(ISNUMBER(W21),ISNUMBER(X21)),X21/W21-1,"") -> 17.196633 | Z21: 17.196633 | AA21: 0.11495601 | AB21: 최근 QoQ≥10% | AC21: =IF(AND(ISNUMBER(N21),ISNUMBER(AA21)),N21-AA21,"") -> 3.600983
A22: CRH plc | B22: CRH | C22: 2026-06-30 | D22: 10777 | E22: 7370 | F22: 9416 | G22: 11069 | H22: 10206 | I22: 2027 | J22: -12 | K22: 1442 | L22: 1971 | M22: 1906 | N22: 0.055947482 | O22: 0.063483736 | P22: 0.46227951 | Q22: -0.21728972 | R22: -0.14933598 | S22: 0.084558103 | T22: 최근 QoQ≥10% | U22: 골재·시멘트·아스팔트 등 건설자재 | V22: Materials | W22: 112.6 | X22: 85.23 | Y22: =IF(AND(ISNUMBER(W22),ISNUMBER(X22)),X22/W22-1,"") -> -0.24307282 | Z22: -0.23458858 | AA22: 0.057178372 | AB22: 최근 QoQ≥10% | AC22: =IF(AND(ISNUMBER(N22),ISNUMBER(AA22)),N22-AA22,"") -> -0.0012308898
A23: Martin Marietta Materials | B23: MLM | C23: 2026-06-30 | D23: 1947 | E23: 1362 | F23: 1533 | G23: 1846 | H23: 1609 | I23: 390 | J23: 167 | K23: 350 | L23: 510 | M23: 415 | N23: 0.21006837 | O23: -0.060240964 | P23: 0.42951542 | Q23: -0.11154599 | R23: -0.1695558 | S23: 0.14729646 | T23: 최근 QoQ≥10% | U23: 골재·시멘트 등 건설자재 | V23: Materials | W23: 606.8 | X23: 490.45 | Y23: =IF(AND(ISNUMBER(W23),ISNUMBER(X23)),X23/W23-1,"") -> -0.19174357 | Z23: -0.18719733 | AA23: 0.026643991 | AB23: 최근 QoQ≥10% | AC23: =IF(AND(ISNUMBER(N23),ISNUMBER(AA23)),N23-AA23,"") -> 0.18342437
A24: Bloom Energy | B24: BE | C24: 2026-06-30 | D24: 1065.365 | E24: 751.054 | F24: 777.683 | G24: 519.048 | H24: 401.242 | I24: 182.237 | J24: 72.19 | K24: 87.529 | L24: 7.846 | M24: -3.503 | N24: 1.6551682 | O24: 흑자전환 | P24: 0.41849321 | Q24: -0.034241458 | R24: 0.49828725 | S24: 0.29360336 | T24: 최근 QoQ≥10% | U24: 고체산화물 연료전지 기반 현장 발전 시스템 (데이터센터 전력 공급) | V24: Industrials | W24: 69.18 | X24: 275.19 | Y24: =IF(AND(ISNUMBER(W24),ISNUMBER(X24)),X24/W24-1,"") -> 2.9778838 | Z24: 2.9778838 | AA24: 0.1950013 | AB24: 최근 QoQ≥10% | AC24: =IF(AND(ISNUMBER(N24),ISNUMBER(AA24)),N24-AA24,"") -> 1.4601669
A25: Chevron Corporation | B25: CVX | C25: 2026-06-30 | D25: 67199 | E25: 47556 | F25: 45787 | G25: 48169 | H25: 44375 | I25: 14276 | J25: 3222 | K25: 4023 | L25: 4297 | M25: 4057 | N25: 0.51434366 | O25: 2.5188563 | P25: 0.41304988 | Q25: 0.038635421 | R25: -0.049450892 | S25: 0.085498592 | T25: 최근 QoQ≥10% | U25: 석유·가스 탐사·생산 및 정제 통합 에너지 | V25: Energy | W25: 159.18 | X25: 205.51 | Y25: =IF(AND(ISNUMBER(W25),ISNUMBER(X25)),X25/W25-1,"") -> 0.29105415 | Z25: 0.34192784 | AA25: -0.12424533 | AC25: =IF(AND(ISNUMBER(N25),ISNUMBER(AA25)),N25-AA25,"") -> 0.63858899
A26: Blackstone Inc. | B26: BX | C26: 2026-06-30 | D26: 4187.932 | E26: 3002.779 | F26: 3736.455 | G26: 2685.881 | H26: 3161.236 | N26: 0.32477676 | P26: 0.39468539 | Q26: -0.19635617 | R26: 0.39114689 | S26: -0.15036998 | T26: 최근 QoQ≥10% | U26: 사모펀드·부동산·신용 대체자산 운용 | V26: Financials | W26: 178.08 | X26: 119.27 | Y26: =IF(AND(ISNUMBER(W26),ISNUMBER(X26)),X26/W26-1,"") -> -0.33024483 | Z26: -0.3030762 | AA26: 0.32739423 | AB26: 최근 QoQ≥10% | AC26: =IF(AND(ISNUMBER(N26),ISNUMBER(AA26)),N26-AA26,"") -> -0.0026174639
A27: ExxonMobil | B27: XOM | C27: 2026-06-30 | D27: 114529 | E27: 83161 | F27: 80039 | G27: 83331 | H27: 79477 | I27: 18195 | J27: 5347 | K27: 6003 | L27: 9178 | M27: 8911 | N27: 0.44103325 | O27: 1.0418584 | P27: 0.37719604 | Q27: 0.039005985 | R27: -0.039505106 | S27: 0.048492017 | T27: 최근 QoQ≥10% | U27: 석유·가스 탐사·생산·정제·화학 통합 에너지 | V27: Energy | W27: 114.56 | X27: 161.23 | Y27: =IF(AND(ISNUMBER(W27),ISNUMBER(X27)),X27/W27-1,"") -> 0.40738478 | Z27: 0.44817457 | AA27: -0.12415646 | AC27: =IF(AND(ISNUMBER(N27),ISNUMBER(AA27)),N27-AA27,"") -> 0.56518971
A28: Valero Energy | B28: VLO | C28: 2026-06-30 | D28: 44476 | E28: 32381 | F28: 30372 | G28: 32168 | H28: 29889 | I28: 5196 | J28: 1731 | K28: 1575 | L28: 1509 | M28: 997 | N28: 0.48803908 | O28: 4.2116349 | P28: 0.37352151 | Q28: 0.066146451 | R28: -0.055831883 | S28: 0.076248787 | T28: 최근 QoQ≥10% | U28: 석유 정제 및 재생연료(에탄올·재생디젤) 생산 | V28: Energy | W28: 170.83 | X28: 375.84 | Y28: =IF(AND(ISNUMBER(W28),ISNUMBER(X28)),X28/W28-1,"") -> 1.200082 | Z28: 1.2467278 | AA28: -0.13340099 | AC28: =IF(AND(ISNUMBER(N28),ISNUMBER(AA28)),N28-AA28,"") -> 0.62144006
A29: Lennox International | B29: LII | C29: 2026-06-30 | D29: 1545.3 | E29: 1135.1 | F29: 1195 | G29: 1426.8 | H29: 1500.9 | I29: 356.4 | J29: 166.1 | K29: 239.6 | L29: 307 | M29: 344.2 | N29: 0.029582251 | O29: 0.035444509 | P29: 0.36137785 | Q29: -0.050125523 | R29: -0.16246145 | S29: -0.049370378 | T29: 최근 QoQ≥10% | U29: 주거·상업용 냉난방공조(HVAC) 설비 | V29: Industrials | W29: 522.44 | X29: 372.34 | Y29: =IF(AND(ISNUMBER(W29),ISNUMBER(X29)),X29/W29-1,"") -> -0.28730572 | Z29: -0.279811 | AA29: 0.034318793 | AB29: 최근 QoQ≥10% | AC29: =IF(AND(ISNUMBER(N29),ISNUMBER(AA29)),N29-AA29,"") -> -0.004736542
A30: Airbnb | B30: ABNB | C30: 2026-06-30 | D30: 3608 | E30: 2678 | F30: 2778 | G30: 4095 | H30: 3096 | I30: 758 | J30: 86 | K30: 269 | L30: 1625 | M30: 612 | N30: 0.16537468 | O30: 0.23856209 | P30: 0.34727409 | Q30: -0.03599712 | R30: -0.32161172 | S30: 0.32267442 | T30: 최근 QoQ≥10% | U30: 숙박 공유·체험 예약 플랫폼 | V30: Consumer Discretionary | W30: 123.08 | X30: 149.58 | Y30: =IF(AND(ISNUMBER(W30),ISNUMBER(X30)),X30/W30-1,"") -> 0.21530712 | Z30: 0.21530711 | AA30: 0.12663755 | AB30: 최근 QoQ≥10% | AC30: =IF(AND(ISNUMBER(N30),ISNUMBER(AA30)),N30-AA30,"") -> 0.038737122
A31: Eversource Energy | B31: ES | C31: 2026-03-31 | D31: 4504.4 | E31: 3370.244 | F31: 3220.6 | G31: 2838.1 | H31: 4118.4 | I31: 1076.185 | J31: 710.512 | K31: 688.657 | L31: 663.081 | M31: 926.439 | N31: 0.093725719 | O31: 0.16163611 | P31: 0.33652044 | Q31: 0.046464634 | R31: 0.13477326 | S31: -0.31087315 | T31: 최근 QoQ≥10% | U31: 뉴잉글랜드 지역 전력·가스·수도 유틸리티 | V31: Utilities | W31: 69.1 | X31: 64.91 | Y31: =IF(AND(ISNUMBER(W31),ISNUMBER(X31)),X31/W31-1,"") -> -0.060636758 | Z31: -0.017227062 | AA31: 0.12020657 | AC31: =IF(AND(ISNUMBER(N31),ISNUMBER(AA31)),N31-AA31,"") -> -0.026480855
A32: Broadcom | B32: AVGO | C32: 2026-07-31 | D32: 29591 | E32: 22187 | F32: 19311 | G32: 18015 | H32: 15952 | I32: 16058 | J32: 10859 | K32: 8666 | L32: 7654 | M32: 6074 | N32: 0.85500251 | O32: 1.6437274 | P32: 0.33370893 | Q32: 0.14893066 | R32: 0.07194005 | S32: 0.12932548 | T32: 최근 QoQ≥10% | U32: 네트워크·맞춤형 AI 반도체 및 인프라 소프트웨어(VMware) | V32: Information Technology | W32: 339.31 | X32: 354.99 | Y32: =IF(AND(ISNUMBER(W32),ISNUMBER(X32)),X32/W32-1,"") -> 0.046211429 | Z32: 0.053990273 | AA32: 0.22031824 | AC32: =IF(AND(ISNUMBER(N32),ISNUMBER(AA32)),N32-AA32,"") -> 0.63468427
A33: KKR & Co. | B33: KKR | C33: 2026-06-30 | D33: 5657.34 | E33: 4252.726 | F33: 5685.044 | G33: 5464.926 | H33: 5002.879 | I33: 325.714 | J33: 456.472 | K33: 356.903 | L33: 512.719 | M33: 327.265 | N33: 0.13081688 | O33: -0.0047392786 | P33: 0.33028556 | Q33: -0.25194493 | R33: 0.040278313 | S33: 0.092356221 | T33: 최근 QoQ≥10% | U33: 사모펀드·인프라·신용 대체자산 운용 및 보험 | V33: Financials | W33: 137.94 | X33: 97.21 | Y33: =IF(AND(ISNUMBER(W33),ISNUMBER(X33)),X33/W33-1,"") -> -0.29527331 | Z33: -0.29016473 | AA33: 0.21978734 | AB33: 최근 QoQ≥10% | AC33: =IF(AND(ISNUMBER(N33),ISNUMBER(AA33)),N33-AA33,"") -> -0.088970464
A34: Booking Holdings | B34: BKNG | C34: 2026-06-30 | D34: 7352 | E34: 5532 | F34: 6349 | G34: 9008 | H34: 6798 | I34: 2500 | J34: 1271 | K34: 2030 | L34: 3940 | M34: 2250 | N34: 0.081494557 | O34: 0.11111111 | P34: 0.32899494 | Q34: -0.12868168 | R34: -0.29518206 | S34: 0.32509562 | T34: 최근 QoQ≥10% | U34: 온라인 숙박·여행 예약 (Booking.com·Priceline) | V34: Consumer Discretionary | W34: 221.024 | X34: 155.9 | Y34: =IF(AND(ISNUMBER(W34),ISNUMBER(X34)),X34/W34-1,"") -> -0.29464674 | Z34: -0.28818948 | AA34: 0.16026626 | AB34: 최근 QoQ≥10% | AC34: =IF(AND(ISNUMBER(N34),ISNUMBER(AA34)),N34-AA34,"") -> -0.0787717
A35: Incyte | B35: INCY | C35: 2026-06-30 | D35: 1674.039 | E35: 1272.676 | F35: 1506.835 | G35: 1365.98 | H35: 1215.529 | I35: 700.389 | J35: 324.173 | K35: 383.963 | L35: 431.296 | M35: 310.812 | N35: 0.37721025 | O35: 1.2534169 | P35: 0.31536935 | Q35: -0.1553979 | R35: 0.10311644 | S35: 0.12377409 | T35: 최근 QoQ≥10% | U35: 항암·면역·피부질환 치료제 바이오제약 | V35: Health Care | W35: 84.16 | X35: 124.64 | Y35: =IF(AND(ISNUMBER(W35),ISNUMBER(X35)),X35/W35-1,"") -> 0.48098859 | Z35: 0.48098852 | AA35: 0.16456864 | AB35: 최근 QoQ≥10% | AC35: =IF(AND(ISNUMBER(N35),ISNUMBER(AA35)),N35-AA35,"") -> 0.21264161
A36: Diamondback Energy | B36: FANG | C36: 2026-06-30 | D36: 5525 | E36: 4210 | F36: 3341 | G36: 3906 | H36: 3651 | I36: 2512 | J36: 1516 | K36: 776 | L36: 1253 | M36: 1139 | N36: 0.51328403 | O36: 1.2054434 | P36: 0.31235154 | Q36: 0.26010177 | R36: -0.14464926 | S36: 0.069843878 | T36: 최근 QoQ≥10% | U36: 퍼미안 분지 원유·천연가스 탐사·생산 | V36: Energy | W36: 144.61 | X36: 185.65 | Y36: =IF(AND(ISNUMBER(W36),ISNUMBER(X36)),X36/W36-1,"") -> 0.2837978 | Z36: 0.31472056 | AA36: 0.48127265 | AC36: =IF(AND(ISNUMBER(N36),ISNUMBER(AA36)),N36-AA36,"") -> 0.032011378
A37: Waters Corporation | B37: WAT | C37: 2026-06-30 | D37: 1645 | E37: 1267 | F37: 932.362 | G37: 799.887 | H37: 771 | I37: -37 | J37: -47 | K37: 270.516 | L37: 192.114 | M37: 191 | N37: 1.1335927 | O37: 적자전환 | P37: 0.29834254 | Q37: 0.35891424 | R37: 0.16561714 | S37: 0.037466926 | T37: 최근 QoQ≥10% | U37: 액체크로마토그래피·질량분석 등 분석기기 및 소프트웨어 | V37: Health Care | W37: 292.65 | X37: 420.57 | Y37: =IF(AND(ISNUMBER(W37),ISNUMBER(X37)),X37/W37-1,"") -> 0.43710917 | Z37: 0.43710923 | AA37: 0.041911104 | AB37: 최근 QoQ≥10% | AC37: =IF(AND(ISNUMBER(N37),ISNUMBER(AA37)),N37-AA37,"") -> 1.0916816
A38: Berkshire Hathaway | B38: BRK-B | C38: 2026-06-30 | D38: 117885 | E38: 92070 | F38: 111442 | G38: 98879 | H38: 83290 | N38: 0.41535599 | P38: 0.28038449 | Q38: -0.17383033 | R38: 0.12705428 | S38: 0.18716533 | T38: 최근 QoQ≥10% | U38: 보험·철도·에너지 유틸리티 등 복합 지주회사 | V38: Financials | W38: 497.09 | X38: 507.17 | Y38: =IF(AND(ISNUMBER(W38),ISNUMBER(X38)),X38/W38-1,"") -> 0.020278018 | Z38: 0.020278053 | AA38: -0.012151239 | AC38: =IF(AND(ISNUMBER(N38),ISNUMBER(AA38)),N38-AA38,"") -> 0.42750722
A39: Trane Technologies | B39: TT | C39: 2026-06-30 | D39: 6353.5 | E39: 4969.4 | F39: 5144.5 | G39: 5742.5 | H39: 5746.4 | I39: 1224.3 | J39: 776.1 | K39: 819 | L39: 1165.3 | M39: 1164.2 | N39: 0.10564875 | O39: 0.051623432 | P39: 0.27852457 | Q39: -0.034036349 | R39: -0.10413583 | S39: -0.00067868579 | T39: 최근 QoQ≥10% | U39: 상업·주거용 냉난방공조(HVAC) 및 운송 냉장 | V39: Industrials | W39: 404.09 | X39: 437.09 | Y39: =IF(AND(ISNUMBER(W39),ISNUMBER(X39)),X39/W39-1,"") -> 0.081664976 | Z39: 0.089303631 | AA39: 0.0827147 | AB39: 최근 QoQ≥10% | AC39: =IF(AND(ISNUMBER(N39),ISNUMBER(AA39)),N39-AA39,"") -> 0.022934054
A40: LyondellBasell | B40: LYB | C40: 2026-06-30 | D40: 9177 | E40: 7197 | F40: 7091 | G40: 7727 | H40: 7658 | I40: 1617 | J40: 254 | K40: -71 | L40: 471 | M40: 317 | N40: 0.19835466 | O40: 4.1009464 | P40: 0.27511463 | Q40: 0.014948526 | R40: -0.082308787 | S40: 0.0090101854 | T40: 최근 QoQ≥10% | U40: 폴리올레핀 등 석유화학 제품 | V40: Materials | W40: 51.37 | X40: 59.97 | Y40: =IF(AND(ISNUMBER(W40),ISNUMBER(X40)),X40/W40-1,"") -> 0.16741289 | Z40: 0.2409767 | AA40: -0.1175386 | AC40: =IF(AND(ISNUMBER(N40),ISNUMBER(AA40)),N40-AA40,"") -> 0.31589327
...

Sheet 수익률 분석
A1: S&P 500 최근 1년 주가수익률 분석 (2025-09-24 종가 → 2026-09-23 종가)
A3: 항목 | B3: 값 | C3: 설명
A4: 수익률 계산 종목 수 | B4: =COUNT(실적!$Y$2:$Y$504) -> 500 | C4: 시작일 이전 상장 종목 (이후 상장·분사 종목 제외)
A5: S&P 500 지수 수익률 (^GSPC) | B5: 0.16090153 | C5: 지수 종가 6,637.97 → 7,706.03 (Yahoo)
A6: 종목 수익률 평균 (동일가중) | B6: =AVERAGE(실적!$Y$2:$Y$504) -> 0.20442869
A7: 종목 수익률 중앙값 | B7: =MEDIAN(실적!$Y$2:$Y$504) -> 0.057288509
A8: 상승 종목 비율 | B8: =COUNTIF(실적!$Y$2:$Y$504,">0")/COUNT(실적!$Y$2:$Y$504) -> 0.57
A9: +50% 이상 종목 수 | B9: =COUNTIF(실적!$Y$2:$Y$504,">=0.5") -> 60
A10: +100% 이상 종목 수 | B10: =COUNTIF(실적!$Y$2:$Y$504,">=1") -> 24
A13: 섹터별 수익률
A14: GICS 섹터 | B14: 종목 수 | C14: 평균 수익률 | D14: 중앙값 수익률 | E14: +50% 이상 종목 수 | F14: +50% 이상 비율 | G14: 중앙값 매출 YoY(현재)
A15: Communication Services | B15: =COUNTIFS(실적!$V$2:$V$504,A15,실적!$Y$2:$Y$504,">-100") -> 23 | C15: =IFERROR(AVERAGEIFS(실적!$Y$2:$Y$504,실적!$V$2:$V$504,A15),"") -> -0.071589283 | D15: {=IFERROR(MEDIAN(IF((실적!$V$2:$V$504=A15)*ISNUMBER(실적!$Y$2:$Y$504),실적!$Y$2:$Y$504)),"")} -> -0.069798214 | E15: =COUNTIFS(실적!$V$2:$V$504,A15,실적!$Y$2:$Y$504,">=0.5") -> 1 | F15: =IFERROR(E15/B15,"") -> 0.043478261 | G15: {=IFERROR(MEDIAN(IF((실적!$V$2:$V$504=A15)*ISNUMBER(실적!$N$2:$N$504),실적!$N$2:$N$504)),"")} -> 0.10810811
A16: Consumer Discretionary | B16: =COUNTIFS(실적!$V$2:$V$504,A16,실적!$Y$2:$Y$504,">-100") -> 47 | C16: =IFERROR(AVERAGEIFS(실적!$Y$2:$Y$504,실적!$V$2:$V$504,A16),"") -> -0.082986304 | D16: {=IFERROR(MEDIAN(IF((실적!$V$2:$V$504=A16)*ISNUMBER(실적!$Y$2:$Y$504),실적!$Y$2:$Y$504)),"")} -> -0.14153436 | E16: =COUNTIFS(실적!$V$2:$V$504,A16,실적!$Y$2:$Y$504,">=0.5") -> 1 | F16: =IFERROR(E16/B16,"") -> 0.021276596 | G16: {=IFERROR(MEDIAN(IF((실적!$V$2:$V$504=A16)*ISNUMBER(실적!$N$2:$N$504),실적!$N$2:$N$504)),"")} -> 0.064786249
A17: Consumer Staples | B17: =COUNTIFS(실적!$V$2:$V$504,A17,실적!$Y$2:$Y$504,">-100") -> 33 | C17: =IFERROR(AVERAGEIFS(실적!$Y$2:$Y$504,실적!$V$2:$V$504,A17),"") -> 0.045557698 | D17: {=IFERROR(MEDIAN(IF((실적!$V$2:$V$504=A17)*ISNUMBER(실적!$Y$2:$Y$504),실적!$Y$2:$Y$504)),"")} -> 0.048042705 | E17: =COUNTIFS(실적!$V$2:$V$504,A17,실적!$Y$2:$Y$504,">=0.5") -> 1 | F17: =IFERROR(E17/B17,"") -> 0.03030303 | G17: {=IFERROR(MEDIAN(IF((실적!$V$2:$V$504=A17)*ISNUMBER(실적!$N$2:$N$504),실적!$N$2:$N$504)),"")} -> 0.052447501
A18: Energy | B18: =COUNTIFS(실적!$V$2:$V$504,A18,실적!$Y$2:$Y$504,">-100") -> 21 | C18: =IFERROR(AVERAGEIFS(실적!$Y$2:$Y$504,실적!$V$2:$V$504,A18),"") -> 0.38243912 | D18: {=IFERROR(MEDIAN(IF((실적!$V$2:$V$504=A18)*ISNUMBER(실적!$Y$2:$Y$504),실적!$Y$2:$Y$504)),"")} -> 0.29105415 | E18: =COUNTIFS(실적!$V$2:$V$504,A18,실적!$Y$2:$Y$504,">=0.5") -> 5 | F18: =IFERROR(E18/B18,"") -> 0.23809524 | G18: {=IFERROR(MEDIAN(IF((실적!$V$2:$V$504=A18)*ISNUMBER(실적!$N$2:$N$504),실적!$N$2:$N$504)),"")} -> 0.36825193
A19: Financials | B19: =COUNTIFS(실적!$V$2:$V$504,A19,실적!$Y$2:$Y$504,">-100") -> 76 | C19: =IFERROR(AVERAGEIFS(실적!$Y$2:$Y$504,실적!$V$2:$V$504,A19),"") -> 0.023087653 | D19: {=IFERROR(MEDIAN(IF((실적!$V$2:$V$504=A19)*ISNUMBER(실적!$Y$2:$Y$504),실적!$Y$2:$Y$504)),"")} -> 0.023124488 | E19: =COUNTIFS(실적!$V$2:$V$504,A19,실적!$Y$2:$Y$504,">=0.5") -> 1 | F19: =IFERROR(E19/B19,"") -> 0.013157895 | G19: {=IFERROR(MEDIAN(IF((실적!$V$2:$V$504=A19)*ISNUMBER(실적!$N$2:$N$504),실적!$N$2:$N$504)),"")} -> 0.10690975
A20: Health Care | B20: =COUNTIFS(실적!$V$2:$V$504,A20,실적!$Y$2:$Y$504,">-100") -> 60 | C20: =IFERROR(AVERAGEIFS(실적!$Y$2:$Y$504,실적!$V$2:$V$504,A20),"") -> 0.3226184 | D20: {=IFERROR(MEDIAN(IF((실적!$V$2:$V$504=A20)*ISNUMBER(실적!$Y$2:$Y$504),실적!$Y$2:$Y$504)),"")} -> 0.22579523 | E20: =COUNTIFS(실적!$V$2:$V$504,A20,실적!$Y$2:$Y$504,">=0.5") -> 10 | F20: =IFERROR(E20/B20,"") -> 0.16666667 | G20: {=IFERROR(MEDIAN(IF((실적!$V$2:$V$504=A20)*ISNUMBER(실적!$N$2:$N$504),실적!$N$2:$N$504)),"")} -> 0.072816706
A21: Industrials | B21: =COUNTIFS(실적!$V$2:$V$504,A21,실적!$Y$2:$Y$504,">-100") -> 81 | C21: =IFERROR(AVERAGEIFS(실적!$Y$2:$Y$504,실적!$V$2:$V$504,A21),"") -> 0.14173537 | D21: {=IFERROR(MEDIAN(IF((실적!$V$2:$V$504=A21)*ISNUMBER(실적!$Y$2:$Y$504),실적!$Y$2:$Y$504)),"")} -> 0.090670751 | E21: =COUNTIFS(실적!$V$2:$V$504,A21,실적!$Y$2:$Y$504,">=0.5") -> 11 | F21: =IFERROR(E21/B21,"") -> 0.13580247 | G21: {=IFERROR(MEDIAN(IF((실적!$V$2:$V$504=A21)*ISNUMBER(실적!$N$2:$N$504),실적!$N$2:$N$504)),"")} -> 0.10100727
A22: Information Technology | B22: =COUNTIFS(실적!$V$2:$V$504,A22,실적!$Y$2:$Y$504,">-100") -> 73 | C22: =IFERROR(AVERAGEIFS(실적!$Y$2:$Y$504,실적!$V$2:$V$504,A22),"") -> 0.88351517 | D22: {=IFERROR(MEDIAN(IF((실적!$V$2:$V$504=A22)*ISNUMBER(실적!$Y$2:$Y$504),실적!$Y$2:$Y$504)),"")} -> 0.27428378 | E22: =COUNTIFS(실적!$V$2:$V$504,A22,실적!$Y$2:$Y$504,">=0.5") -> 27 | F22: =IFERROR(E22/B22,"") -> 0.36986301 | G22: {=IFERROR(MEDIAN(IF((실적!$V$2:$V$504=A22)*ISNUMBER(실적!$N$2:$N$504),실적!$N$2:$N$504)),"")} -> 0.22477998
A23: Materials | B23: =COUNTIFS(실적!$V$2:$V$504,A23,실적!$Y$2:$Y$504,">-100") -> 25 | C23: =IFERROR(AVERAGEIFS(실적!$Y$2:$Y$504,실적!$V$2:$V$504,A23),"") -> 0.16038251 | D23: {=IFERROR(MEDIAN(IF((실적!$V$2:$V$504=A23)*ISNUMBER(실적!$Y$2:$Y$504),실적!$Y$2:$Y$504)),"")} -> 0.074913295 | E23: =COUNTIFS(실적!$V$2:$V$504,A23,실적!$Y$2:$Y$504,">=0.5") -> 3 | F23: =IFERROR(E23/B23,"") -> 0.12 | G23: {=IFERROR(MEDIAN(IF((실적!$V$2:$V$504=A23)*ISNUMBER(실적!$N$2:$N$504),실적!$N$2:$N$504)),"")} -> 0.1091646
A24: Real Estate | B24: =COUNTIFS(실적!$V$2:$V$504,A24,실적!$Y$2:$Y$504,">-100") -> 30 | C24: =IFERROR(AVERAGEIFS(실적!$Y$2:$Y$504,실적!$V$2:$V$504,A24),"") -> -0.027859196 | D24: {=IFERROR(MEDIAN(IF((실적!$V$2:$V$504=A24)*ISNUMBER(실적!$Y$2:$Y$504),실적!$Y$2:$Y$504)),"")} -> -0.043570897 | E24: =COUNTIFS(실적!$V$2:$V$504,A24,실적!$Y$2:$Y$504,">=0.5") -> 0 | F24: =IFERROR(E24/B24,"") -> 0 | G24: {=IFERROR(MEDIAN(IF((실적!$V$2:$V$504=A24)*ISNUMBER(실적!$N$2:$N$504),실적!$N$2:$N$504)),"")} -> 0.057094835
A25: Utilities | B25: =COUNTIFS(실적!$V$2:$V$504,A25,실적!$Y$2:$Y$504,">-100") -> 31 | C25: =IFERROR(AVERAGEIFS(실적!$Y$2:$Y$504,실적!$V$2:$V$504,A25),"") -> -0.065680422 | D25: {=IFERROR(MEDIAN(IF((실적!$V$2:$V$504=A25)*ISNUMBER(실적!$Y$2:$Y$504),실적!$Y$2:$Y$504)),"")} -> -0.063140853 | E25: =COUNTIFS(실적!$V$2:$V$504,A25,실적!$Y$2:$Y$504,">=0.5") -> 0 | F25: =IFERROR(E25/B25,"") -> 0 | G25: {=IFERROR(MEDIAN(IF((실적!$V$2:$V$504=A25)*ISNUMBER(실적!$N$2:$N$504),실적!$N$2:$N$504)),"")} -> 0.04964539
A26: ※ 섹터 행은 필터로 정렬 가능. 평균은 극단값 영향이 크므로 중앙값을 함께 볼 것
A28: 수익률 5분위별 특징 (1분위 = 수익률 상위 20%)
A29: 분위 | B29: 수익률 하한 | C29: 수익률 상한 | D29: 종목 수 | E29: 중앙값 수익률 | F29: 중앙값 매출 YoY(현재) | G29: 중앙값 영업이익 YoY(현재) | H29: 중앙값 최근 매출 QoQ(현재) | I29: 현재 선정(①②) 비율 | J29: 중앙값 매출 YoY(2025-09-24) | K29: 2025-09-24 선정(①②) 비율 | L29: 중앙값 매출 YoY 변화(%p)
A30: 1분위 | B30: =PERCENTILE(실적!$Y$2:$Y$504,0.8) -> 0.35182857 | C30: =PERCENTILE(실적!$Y$2:$Y$504,1) -> 17.196633 | D30: =COUNTIFS(실적!$Y$2:$Y$504,">="&B30,실적!$Y$2:$Y$504,"<="&C30) -> 100 | E30: {=IFERROR(MEDIAN(IF((ISNUMBER(실적!$Y$2:$Y$504)*(실적!$Y$2:$Y$504>=B30)*(실적!$Y$2:$Y$504<=C30))*ISNUMBER(실적!$Y$2:$Y$504),실적!$Y$2:$Y$504)),"")} -> 0.5600203 | F30: {=IFERROR(MEDIAN(IF((ISNUMBER(실적!$Y$2:$Y$504)*(실적!$Y$2:$Y$504>=B30)*(실적!$Y$2:$Y$504<=C30))*ISNUMBER(실적!$N$2:$N$504),실적!$N$2:$N$504)),"")} -> 0.190212 | G30: {=IFERROR(MEDIAN(IF((ISNUMBER(실적!$Y$2:$Y$504)*(실적!$Y$2:$Y$504>=B30)*(실적!$Y$2:$Y$504<=C30))*ISNUMBER(실적!$O$2:$O$504),실적!$O$2:$O$504)),"")} -> 0.32304217 | H30: {=IFERROR(MEDIAN(IF((ISNUMBER(실적!$Y$2:$Y$504)*(실적!$Y$2:$Y$504>=B30)*(실적!$Y$2:$Y$504<=C30))*ISNUMBER(실적!$P$2:$P$504),실적!$P$2:$P$504)),"")} -> 0.09730151 | I30: {=IFERROR(SUM((ISNUMBER(실적!$Y$2:$Y$504)*(실적!$Y$2:$Y$504>=B30)*(실적!$Y$2:$Y$504<=C30))*(실적!$T$2:$T$504<>""))/D30,"")} -> 0.56 | J30: {=IFERROR(MEDIAN(IF((ISNUMBER(실적!$Y$2:$Y$504)*(실적!$Y$2:$Y$504>=B30)*(실적!$Y$2:$Y$504<=C30))*ISNUMBER(실적!$AA$2:$AA$504),실적!$AA$2:$AA$504)),"")} -> 0.075575429 | K30: {=IFERROR(SUM((ISNUMBER(실적!$Y$2:$Y$504)*(실적!$Y$2:$Y$504>=B30)*(실적!$Y$2:$Y$504<=C30))*(실적!$AB$2:$AB$504<>""))/D30,"")} -> 0.28 | L30: {=IFERROR(MEDIAN(IF((ISNUMBER(실적!$Y$2:$Y$504)*(실적!$Y$2:$Y$504>=B30)*(실적!$Y$2:$Y$504<=C30))*ISNUMBER(실적!$AC$2:$AC$504),실적!$AC$2:$AC$504)),"")} -> 0.10526819
A31: 2분위 | B31: =PERCENTILE(실적!$Y$2:$Y$504,0.6) -> 0.12062516 | C31: =PERCENTILE(실적!$Y$2:$Y$504,0.8) -> 0.35182857 | D31: =COUNTIFS(실적!$Y$2:$Y$504,">="&B31,실적!$Y$2:$Y$504,"<"&C31) -> 100 | E31: {=IFERROR(MEDIAN(IF((ISNUMBER(실적!$Y$2:$Y$504)*(실적!$Y$2:$Y$504>=B31)*(실적!$Y$2:$Y$504<C31))*ISNUMBER(실적!$Y$2:$Y$504),실적!$Y$2:$Y$504)),"")} -> 0.2063321 | F31: {=IFERROR(MEDIAN(IF((ISNUMBER(실적!$Y$2:$Y$504)*(실적!$Y$2:$Y$504>=B31)*(실적!$Y$2:$Y$504<C31))*ISNUMBER(실적!$N$2:$N$504),실적!$N$2:$N$504)),"")} -> 0.10488887 | G31: {=IFERROR(MEDIAN(IF((ISNUMBER(실적!$Y$2:$Y$504)*(실적!$Y$2:$Y$504>=B31)*(실적!$Y$2:$Y$504<C31))*ISNUMBER(실적!$O$2:$O$504),실적!$O$2:$O$504)),"")} -> 0.23228676 | H31: {=IFERROR(MEDIAN(IF((ISNUMBER(실적!$Y$2:$Y$504)*(실적!$Y$2:$Y$504>=B31)*(실적!$Y$2:$Y$504<C31))*ISNUMBER(실적!$P$2:$P$504),실적!$P$2:$P$504)),"")} -> 0.070487467 | I31: {=IFERROR(SUM((ISNUMBER(실적!$Y$2:$Y$504)*(실적!$Y$2:$Y$504>=B31)*(실적!$Y$2:$Y$504<C31))*(실적!$T$2:$T$504<>""))/D31,"")} -> 0.4 | J31: {=IFERROR(MEDIAN(IF((ISNUMBER(실적!$Y$2:$Y$504)*(실적!$Y$2:$Y$504>=B31)*(실적!$Y$2:$Y$504<C31))*ISNUMBER(실적!$AA$2:$AA$504),실적!$AA$2:$AA$504)),"")} -> 0.061448241 | K31: {=IFERROR(SUM((ISNUMBER(실적!$Y$2:$Y$504)*(실적!$Y$2:$Y$504>=B31)*(실적!$Y$2:$Y$504<C31))*(실적!$AB$2:$AB$504<>""))/D31,"")} -> 0.23 | L31: {=IFERROR(MEDIAN(IF((ISNUMBER(실적!$Y$2:$Y$504)*(실적!$Y$2:$Y$504>=B31)*(실적!$Y$2:$Y$504<C31))*ISNUMBER(실적!$AC$2:$AC$504),실적!$AC$2:$AC$504)),"")} -> 0.046424762
A32: 3분위 | B32: =PERCENTILE(실적!$Y$2:$Y$504,0.4) -> -0.02499773 | C32: =PERCENTILE(실적!$Y$2:$Y$504,0.6) -> 0.12062516 | D32: =COUNTIFS(실적!$Y$2:$Y$504,">="&B32,실적!$Y$2:$Y$504,"<"&C32) -> 100 | E32: {=IFERROR(MEDIAN(IF((ISNUMBER(실적!$Y$2:$Y$504)*(실적!$Y$2:$Y$504>=B32)*(실적!$Y$2:$Y$504<C32))*ISNUMBER(실적!$Y$2:$Y$504),실적!$Y$2:$Y$504)),"")} -> 0.057288509 | F32: {=IFERROR(MEDIAN(IF((ISNUMBER(실적!$Y$2:$Y$504)*(실적!$Y$2:$Y$504>=B32)*(실적!$Y$2:$Y$504<C32))*ISNUMBER(실적!$N$2:$N$504),실적!$N$2:$N$504)),"")} -> 0.094227319 | G32: {=IFERROR(MEDIAN(IF((ISNUMBER(실적!$Y$2:$Y$504)*(실적!$Y$2:$Y$504>=B32)*(실적!$Y$2:$Y$504<C32))*ISNUMBER(실적!$O$2:$O$504),실적!$O$2:$O$504)),"")} -> 0.11423805 | H32: {=IFERROR(MEDIAN(IF((ISNUMBER(실적!$Y$2:$Y$504)*(실적!$Y$2:$Y$504>=B32)*(실적!$Y$2:$Y$504<C32))*ISNUMBER(실적!$P$2:$P$504),실적!$P$2:$P$504)),"")} -> 0.054581873 | I32: {=IFERROR(SUM((ISNUMBER(실적!$Y$2:$Y$504)*(실적!$Y$2:$Y$504>=B32)*(실적!$Y$2:$Y$504<C32))*(실적!$T$2:$T$504<>""))/D32,"")} -> 0.23 | J32: {=IFERROR(MEDIAN(IF((ISNUMBER(실적!$Y$2:$Y$504)*(실적!$Y$2:$Y$504>=B32)*(실적!$Y$2:$Y$504<C32))*ISNUMBER(실적!$AA$2:$AA$504),실적!$AA$2:$AA$504)),"")} -> 0.058899509 | K32: {=IFERROR(SUM((ISNUMBER(실적!$Y$2:$Y$504)*(실적!$Y$2:$Y$504>=B32)*(실적!$Y$2:$Y$504<C32))*(실적!$AB$2:$AB$504<>""))/D32,"")} -> 0.19 | L32: {=IFERROR(MEDIAN(IF((ISNUMBER(실적!$Y$2:$Y$504)*(실적!$Y$2:$Y$504>=B32)*(실적!$Y$2:$Y$504<C32))*ISNUMBER(실적!$AC$2:$AC$504),실적!$AC$2:$AC$504)),"")} -> 0.029301896
A33: 4분위 | B33: =PERCENTILE(실적!$Y$2:$Y$504,0.2) -> -0.15350808 | C33: =PERCENTILE(실적!$Y$2:$Y$504,0.4) -> -0.02499773 | D33: =COUNTIFS(실적!$Y$2:$Y$504,">="&B33,실적!$Y$2:$Y$504,"<"&C33) -> 100 | E33: {=IFERROR(MEDIAN(IF((ISNUMBER(실적!$Y$2:$Y$504)*(실적!$Y$2:$Y$504>=B33)*(실적!$Y$2:$Y$504<C33))*ISNUMBER(실적!$Y$2:$Y$504),실적!$Y$2:$Y$504)),"")} -> -0.080935444 | F33: {=IFERROR(MEDIAN(IF((ISNUMBER(실적!$Y$2:$Y$504)*(실적!$Y$2:$Y$504>=B33)*(실적!$Y$2:$Y$504<C33))*ISNUMBER(실적!$N$2:$N$504),실적!$N$2:$N$504)),"")} -> 0.066305667 | G33: {=IFERROR(MEDIAN(IF((ISNUMBER(실적!$Y$2:$Y$504)*(실적!$Y$2:$Y$504>=B33)*(실적!$Y$2:$Y$504<C33))*ISNUMBER(실적!$O$2:$O$504),실적!$O$2:$O$504)),"")} -> 0.10473791 | H33: {=IFERROR(MEDIAN(IF((ISNUMBER(실적!$Y$2:$Y$504)*(실적!$Y$2:$Y$504>=B33)*(실적!$Y$2:$Y$504<C33))*ISNUMBER(실적!$P$2:$P$504),실적!$P$2:$P$504)),"")} -> 0.03366442 | I33: {=IFERROR(SUM((ISNUMBER(실적!$Y$2:$Y$504)*(실적!$Y$2:$Y$504>=B33)*(실적!$Y$2:$Y$504<C33))*(실적!$T$2:$T$504<>""))/D33,"")} -> 0.21 | J33: {=IFERROR(MEDIAN(IF((ISNUMBER(실적!$Y$2:$Y$504)*(실적!$Y$2:$Y$504>=B33)*(실적!$Y$2:$Y$504<C33))*ISNUMBER(실적!$AA$2:$AA$504),실적!$AA$2:$AA$504)),"")} -> 0.075135925 | K33: {=IFERROR(SUM((ISNUMBER(실적!$Y$2:$Y$504)*(실적!$Y$2:$Y$504>=B33)*(실적!$Y$2:$Y$504<C33))*(실적!$AB$2:$AB$504<>""))/D33,"")} -> 0.21 | L33: {=IFERROR(MEDIAN(IF((ISNUMBER(실적!$Y$2:$Y$504)*(실적!$Y$2:$Y$504>=B33)*(실적!$Y$2:$Y$504<C33))*ISNUMBER(실적!$AC$2:$AC$504),실적!$AC$2:$AC$504)),"")} -> 0.005527118
A34: 5분위 | B34: =PERCENTILE(실적!$Y$2:$Y$504,0) -> -0.66377156 | C34: =PERCENTILE(실적!$Y$2:$Y$504,0.2) -> -0.15350808 | D34: =COUNTIFS(실적!$Y$2:$Y$504,">="&B34,실적!$Y$2:$Y$504,"<"&C34) -> 100 | E34: {=IFERROR(MEDIAN(IF((ISNUMBER(실적!$Y$2:$Y$504)*(실적!$Y$2:$Y$504>=B34)*(실적!$Y$2:$Y$504<C34))*ISNUMBER(실적!$Y$2:$Y$504),실적!$Y$2:$Y$504)),"")} -> -0.29315231 | F34: {=IFERROR(MEDIAN(IF((ISNUMBER(실적!$Y$2:$Y$504)*(실적!$Y$2:$Y$504>=B34)*(실적!$Y$2:$Y$504<C34))*ISNUMBER(실적!$N$2:$N$504),실적!$N$2:$N$504)),"")} -> 0.057612069 | G34: {=IFERROR(MEDIAN(IF((ISNUMBER(실적!$Y$2:$Y$504)*(실적!$Y$2:$Y$504>=B34)*(실적!$Y$2:$Y$504<C34))*ISNUMBER(실적!$O$2:$O$504),실적!$O$2:$O$504)),"")} -> 0.028207598 | H34: {=IFERROR(MEDIAN(IF((ISNUMBER(실적!$Y$2:$Y$504)*(실적!$Y$2:$Y$504>=B34)*(실적!$Y$2:$Y$504<C34))*ISNUMBER(실적!$P$2:$P$504),실적!$P$2:$P$504)),"")} -> 0.036633207 | I34: {=IFERROR(SUM((ISNUMBER(실적!$Y$2:$Y$504)*(실적!$Y$2:$Y$504>=B34)*(실적!$Y$2:$Y$504<C34))*(실적!$T$2:$T$504<>""))/D34,"")} -> 0.25 | J34: {=IFERROR(MEDIAN(IF((ISNUMBER(실적!$Y$2:$Y$504)*(실적!$Y$2:$Y$504>=B34)*(실적!$Y$2:$Y$504<C34))*ISNUMBER(실적!$AA$2:$AA$504),실적!$AA$2:$AA$504)),"")} -> 0.07033151 | K34: {=IFERROR(SUM((ISNUMBER(실적!$Y$2:$Y$504)*(실적!$Y$2:$Y$504>=B34)*(실적!$Y$2:$Y$504<C34))*(실적!$AB$2:$AB$504<>""))/D34,"")} -> 0.31 | L34: {=IFERROR(MEDIAN(IF((ISNUMBER(실적!$Y$2:$Y$504)*(실적!$Y$2:$Y$504>=B34)*(실적!$Y$2:$Y$504<C34))*ISNUMBER(실적!$AC$2:$AC$504),실적!$AC$2:$AC$504)),"")} -> -0.016505507
A35: ※ 영업이익 YoY 중앙값은 숫자 값만 사용 ('흑자전환'·'N/M' 등 제외). '현재' = 이 파일의 최근 5개 분기, 1년 전 = SEC 제출 자료 기준 당시 최근 5개 분기
A38: 1년 주가수익률 상위 30 종목
A39: 순위 | B39: 티커 | C39: 기업명 | D39: GICS 섹터 | E39: 1년 주가수익률 | F39: 매출 YoY(현재) | G39: 최근 QoQ(현재) | H39: 현재 선정 기준 | I39: 매출 YoY(2025-09-24) | J39: 2025-09-24 선정 기준 | K39: 주요 사업
A40: 1 | B40: SNDK | C40: =IF(INDEX(실적!$A$2:$A$504,MATCH($B40,실적!$B$2:$B$504,0))="","",INDEX(실적!$A$2:$A$504,MATCH($B40,실적!$B$2:$B$504,0))) -> Sandisk | D40: =IF(INDEX(실적!$V$2:$V$504,MATCH($B40,실적!$B$2:$B$504,0))="","",INDEX(실적!$V$2:$V$504,MATCH($B40,실적!$B$2:$B$504,0))) -> Information Technology | E40: =IF(INDEX(실적!$Y$2:$Y$504,MATCH($B40,실적!$B$2:$B$504,0))="","",INDEX(실적!$Y$2:$Y$504,MATCH($B40,실적!$B$2:$B$504,0))) -> 17.196633 | F40: =IF(INDEX(실적!$N$2:$N$504,MATCH($B40,실적!$B$2:$B$504,0))="","",INDEX(실적!$N$2:$N$504,MATCH($B40,실적!$B$2:$B$504,0))) -> 3.715939 | G40: =IF(INDEX(실적!$P$2:$P$504,MATCH($B40,실적!$B$2:$B$504,0))="","",INDEX(실적!$P$2:$P$504,MATCH($B40,실적!$B$2:$B$504,0))) -> 0.50672269 | H40: =IF(INDEX(실적!$T$2:$T$504,MATCH($B40,실적!$B$2:$B$504,0))="","",INDEX(실적!$T$2:$T$504,MATCH($B40,실적!$B$2:$B$504,0))) -> 최근 QoQ≥10% | I40: =IF(INDEX(실적!$AA$2:$AA$504,MATCH($B40,실적!$B$2:$B$504,0))="","",INDEX(실적!$AA$2:$AA$504,MATCH($B40,실적!$B$2:$B$504,0))) -> 0.11495601 | J40: =IF(INDEX(실적!$AB$2:$AB$504,MATCH($B40,실적!$B$2:$B$504,0))="","",INDEX(실적!$AB$2:$AB$504,MATCH($B40,실적!$B$2:$B$504,0))) -> 최근 QoQ≥10% | K40: =IF(INDEX(실적!$U$2:$U$504,MATCH($B40,실적!$B$2:$B$504,0))="","",INDEX(실적!$U$2:$U$504,MATCH($B40,실적!$B$2:$B$504,0))) -> 낸드 플래시 메모리·SSD 등 데이터 저장장치 제조 (WD에서 분사)
A41: 2 | B41: MRNA | C41: =IF(INDEX(실적!$A$2:$A$504,MATCH($B41,실적!$B$2:$B$504,0))="","",INDEX(실적!$A$2:$A$504,MATCH($B41,실적!$B$2:$B$504,0))) -> Moderna | D41: =IF(INDEX(실적!$V$2:$V$504,MATCH($B41,실적!$B$2:$B$504,0))="","",INDEX(실적!$V$2:$V$504,MATCH($B41,실적!$B$2:$B$504,0))) -> Health Care | E41: =IF(INDEX(실적!$Y$2:$Y$504,MATCH($B41,실적!$B$2:$B$504,0))="","",INDEX(실적!$Y$2:$Y$504,MATCH($B41,실적!$B$2:$B$504,0))) -> 6.0367079 | F41: =IF(INDEX(실적!$N$2:$N$504,MATCH($B41,실적!$B$2:$B$504,0))="","",INDEX(실적!$N$2:$N$504,MATCH($B41,실적!$B$2:$B$504,0))) -> 0.04379562 | G41: =IF(INDEX(실적!$P$2:$P$504,MATCH($B41,실적!$B$2:$B$504,0))="","",INDEX(실적!$P$2:$P$504,MATCH($B41,실적!$B$2:$B$504,0))) -> -0.63239075 | H41: =IF(INDEX(실적!$T$2:$T$504,MATCH($B41,실적!$B$2:$B$504,0))="","",INDEX(실적!$T$2:$T$504,MATCH($B41,실적!$B$2:$B$504,0))) | I41: =IF(INDEX(실적!$AA$2:$AA$504,MATCH($B41,실적!$B$2:$B$504,0))="","",INDEX(실적!$AA$2:$AA$504,MATCH($B41,실적!$B$2:$B$504,0))) -> -0.41078838 | J41: =IF(INDEX(실적!$AB$2:$AB$504,MATCH($B41,실적!$B$2:$B$504,0))="","",INDEX(실적!$AB$2:$AB$504,MATCH($B41,실적!$B$2:$B$504,0))) -> 최근 QoQ≥10% | K41: mRNA 백신·치료제 (코로나·RSV)
A42: 3 | B42: MU | C42: =IF(INDEX(실적!$A$2:$A$504,MATCH($B42,실적!$B$2:$B$504,0))="","",INDEX(실적!$A$2:$A$504,MATCH($B42,실적!$B$2:$B$504,0))) -> Micron Technology | D42: =IF(INDEX(실적!$V$2:$V$504,MATCH($B42,실적!$B$2:$B$504,0))="","",INDEX(실적!$V$2:$V$504,MATCH($B42,실적!$B$2:$B$504,0))) -> Information Technology | E42: =IF(INDEX(실적!$Y$2:$Y$504,MATCH($B42,실적!$B$2:$B$504,0))="","",INDEX(실적!$Y$2:$Y$504,MATCH($B42,실적!$B$2:$B$504,0))) -> 5.6284089 | F42: =IF(INDEX(실적!$N$2:$N$504,MATCH($B42,실적!$B$2:$B$504,0))="","",INDEX(실적!$N$2:$N$504,MATCH($B42,실적!$B$2:$B$504,0))) -> 3.4571551 | G42: =IF(INDEX(실적!$P$2:$P$504,MATCH($B42,실적!$B$2:$B$504,0))="","",INDEX(실적!$P$2:$P$504,MATCH($B42,실적!$B$2:$B$504,0))) -> 0.73746857 | H42: =IF(INDEX(실적!$T$2:$T$504,MATCH($B42,실적!$B$2:$B$504,0))="","",INDEX(실적!$T$2:$T$504,MATCH($B42,실적!$B$2:$B$504,0))) -> 최근 QoQ≥10% | I42: =IF(INDEX(실적!$AA$2:$AA$504,MATCH($B42,실적!$B$2:$B$504,0))="","",INDEX(실적!$AA$2:$AA$504,MATCH($B42,실적!$B$2:$B$504,0))) -> 0.36558508 | J42: =IF(INDEX(실적!$AB$2:$AB$504,MATCH($B42,실적!$B$2:$B$504,0))="","",INDEX(실적!$AB$2:$AB$504,MATCH($B42,실적!$B$2:$B$504,0))) -> 최근 QoQ≥10% | K42: =IF(INDEX(실적!$U$2:$U$504,MATCH($B42,실적!$B$2:$B$504,0))="","",INDEX(실적!$U$2:$U$504,MATCH($B42,실적!$B$2:$B$504,0))) -> D램·낸드 메모리 반도체 제조 (AI 서버용 HBM 포함)
A43: 4 | B43: LITE | C43: =IF(INDEX(실적!$A$2:$A$504,MATCH($B43,실적!$B$2:$B$504,0))="","",INDEX(실적!$A$2:$A$504,MATCH($B43,실적!$B$2:$B$504,0))) -> Lumentum | D43: =IF(INDEX(실적!$V$2:$V$504,MATCH($B43,실적!$B$2:$B$504,0))="","",INDEX(실적!$V$2:$V$504,MATCH($B43,실적!$B$2:$B$504,0))) -> Information Technology | E43: =IF(INDEX(실적!$Y$2:$Y$504,MATCH($B43,실적!$B$2:$B$504,0))="","",INDEX(실적!$Y$2:$Y$504,MATCH($B43,실적!$B$2:$B$504,0))) -> 5.1342062 | F43: =IF(INDEX(실적!$N$2:$N$504,MATCH($B43,실적!$B$2:$B$504,0))="","",INDEX(실적!$N$2:$N$504,MATCH($B43,실적!$B$2:$B$504,0))) -> 1.0934055 | G43: =IF(INDEX(실적!$P$2:$P$504,MATCH($B43,실적!$B$2:$B$504,0))="","",INDEX(실적!$P$2:$P$504,MATCH($B43,실적!$B$2:$B$504,0))) -> 0.24480455 | H43: =IF(INDEX(실적!$T$2:$T$504,MATCH($B43,실적!$B$2:$B$504,0))="","",INDEX(실적!$T$2:$T$504,MATCH($B43,실적!$B$2:$B$504,0))) -> 최근 QoQ≥10% | I43: =IF(INDEX(실적!$AA$2:$AA$504,MATCH($B43,실적!$B$2:$B$504,0))="","",INDEX(실적!$AA$2:$AA$504,MATCH($B43,실적!$B$2:$B$504,0))) -> 0.55919559 | J43: =IF(INDEX(실적!$AB$2:$AB$504,MATCH($B43,실적!$B$2:$B$504,0))="","",INDEX(실적!$AB$2:$AB$504,MATCH($B43,실적!$B$2:$B$504,0))) -> 최근 QoQ≥10% | K43: =IF(INDEX(실적!$U$2:$U$504,MATCH($B43,실적!$B$2:$B$504,0))="","",INDEX(실적!$U$2:$U$504,MATCH($B43,실적!$B$2:$B$504,0))) -> 광통신 부품·레이저 (데이터센터용 광트랜시버)
A44: 5 | B44: WDC | C44: =IF(INDEX(실적!$A$2:$A$504,MATCH($B44,실적!$B$2:$B$504,0))="","",INDEX(실적!$A$2:$A$504,MATCH($B44,실적!$B$2:$B$504,0))) -> Western Digital | D44: =IF(INDEX(실적!$V$2:$V$504,MATCH($B44,실적!$B$2:$B$504,0))="","",INDEX(실적!$V$2:$V$504,MATCH($B44,실적!$B$2:$B$504,0))) -> Information Technology | E44: =IF(INDEX(실적!$Y$2:$Y$504,MATCH($B44,실적!$B$2:$B$504,0))="","",INDEX(실적!$Y$2:$Y$504,MATCH($B44,실적!$B$2:$B$504,0))) -> 3.3184429 | F44: =IF(INDEX(실적!$N$2:$N$504,MATCH($B44,실적!$B$2:$B$504,0))="","",INDEX(실적!$N$2:$N$504,MATCH($B44,실적!$B$2:$B$504,0))) -> 0.43838772 | G44: =IF(INDEX(실적!$P$2:$P$504,MATCH($B44,실적!$B$2:$B$504,0))="","",INDEX(실적!$P$2:$P$504,MATCH($B44,실적!$B$2:$B$504,0))) -> 0.12286485 | H44: =IF(INDEX(실적!$T$2:$T$504,MATCH($B44,실적!$B$2:$B$504,0))="","",INDEX(실적!$T$2:$T$504,MATCH($B44,실적!$B$2:$B$504,0))) -> 최근 QoQ≥10% | I44: =IF(INDEX(실적!$AA$2:$AA$504,MATCH($B44,실적!$B$2:$B$504,0))="","",INDEX(실적!$AA$2:$AA$504,MATCH($B44,실적!$B$2:$B$504,0))) -> 0.2999002 | J44: =IF(INDEX(실적!$AB$2:$AB$504,MATCH($B44,실적!$B$2:$B$504,0))="","",INDEX(실적!$AB$2:$AB$504,MATCH($B44,실적!$B$2:$B$504,0))) -> 최근 QoQ≥10% | K44: =IF(INDEX(실적!$U$2:$U$504,MATCH($B44,실적!$B$2:$B$504,0))="","",INDEX(실적!$U$2:$U$504,MATCH($B44,실적!$B$2:$B$504,0))) -> 하드디스크(HDD) 데이터 저장장치
A45: 6 | B45: DELL | C45: =IF(INDEX(실적!$A$2:$A$504,MATCH($B45,실적!$B$2:$B$504,0))="","",INDEX(실적!$A$2:$A$504,MATCH($B45,실적!$B$2:$B$504,0))) -> Dell Technologies | D45: =IF(INDEX(실적!$V$2:$V$504,MATCH($B45,실적!$B$2:$B$504,0))="","",INDEX(실적!$V$2:$V$504,MATCH($B45,실적!$B$2:$B$504,0))) -> Information Technology | E45: =IF(INDEX(실적!$Y$2:$Y$504,MATCH($B45,실적!$B$2:$B$504,0))="","",INDEX(실적!$Y$2:$Y$504,MATCH($B45,실적!$B$2:$B$504,0))) -> 3.1625407 | F45: =IF(INDEX(실적!$N$2:$N$504,MATCH($B45,실적!$B$2:$B$504,0))="","",INDEX(실적!$N$2:$N$504,MATCH($B45,실적!$B$2:$B$504,0))) -> 0.57747851 | G45: =IF(INDEX(실적!$P$2:$P$504,MATCH($B45,실적!$B$2:$B$504,0))="","",INDEX(실적!$P$2:$P$504,MATCH($B45,실적!$B$2:$B$504,0))) -> 0.071369919 | H45: =IF(INDEX(실적!$T$2:$T$504,MATCH($B45,실적!$B$2:$B$504,0))="","",INDEX(실적!$T$2:$T$504,MATCH($B45,실적!$B$2:$B$504,0))) | I45: =IF(INDEX(실적!$AA$2:$AA$504,MATCH($B45,실적!$B$2:$B$504,0))="","",INDEX(실적!$AA$2:$AA$504,MATCH($B45,실적!$B$2:$B$504,0))) -> 0.18980261 | J45: =IF(INDEX(실적!$AB$2:$AB$504,MATCH($B45,실적!$B$2:$B$504,0))="","",INDEX(실적!$AB$2:$AB$504,MATCH($B45,실적!$B$2:$B$504,0))) -> 최근 QoQ≥10% | K45: PC·서버(AI 서버)·스토리지
A46: 7 | B46: STX | C46: =IF(INDEX(실적!$A$2:$A$504,MATCH($B46,실적!$B$2:$B$504,0))="","",INDEX(실적!$A$2:$A$504,MATCH($B46,실적!$B$2:$B$504,0))) -> Seagate Technology | D46: =IF(INDEX(실적!$V$2:$V$504,MATCH($B46,실적!$B$2:$B$504,0))="","",INDEX(실적!$V$2:$V$504,MATCH($B46,실적!$B$2:$B$504,0))) -> Information Technology | E46: =IF(INDEX(실적!$Y$2:$Y$504,MATCH($B46,실적!$B$2:$B$504,0))="","",INDEX(실적!$Y$2:$Y$504,MATCH($B46,실적!$B$2:$B$504,0))) -> 3.1299061 | F46: =IF(INDEX(실적!$N$2:$N$504,MATCH($B46,실적!$B$2:$B$504,0))="","",INDEX(실적!$N$2:$N$504,MATCH($B46,실적!$B$2:$B$504,0))) -> 0.48486088 | G46: =IF(INDEX(실적!$P$2:$P$504,MATCH($B46,실적!$B$2:$B$504,0))="","",INDEX(실적!$P$2:$P$504,MATCH($B46,실적!$B$2:$B$504,0))) -> 0.16613111 | H46: =IF(INDEX(실적!$T$2:$T$504,MATCH($B46,실적!$B$2:$B$504,0))="","",INDEX(실적!$T$2:$T$504,MATCH($B46,실적!$B$2:$B$504,0))) -> 최근 QoQ≥10% | I46: =IF(INDEX(실적!$AA$2:$AA$504,MATCH($B46,실적!$B$2:$B$504,0))="","",INDEX(실적!$AA$2:$AA$504,MATCH($B46,실적!$B$2:$B$504,0))) -> 0.29517753 | J46: =IF(INDEX(실적!$AB$2:$AB$504,MATCH($B46,실적!$B$2:$B$504,0))="","",INDEX(실적!$AB$2:$AB$504,MATCH($B46,실적!$B$2:$B$504,0))) -> 최근 QoQ≥10% | K46: =IF(INDEX(실적!$U$2:$U$504,MATCH($B46,실적!$B$2:$B$504,0))="","",INDEX(실적!$U$2:$U$504,MATCH($B46,실적!$B$2:$B$504,0))) -> 하드디스크(HDD) 등 데이터 저장장치
...

Sheet 메모
A1: 데이터 출처 | B1: Yahoo Finance via yfinance (yf.Ticker(t).quarterly_income_stmt: Total Revenue / Operating Income)
A2: 종목 리스트 출처 | B2: https://en.wikipedia.org/wiki/List_of_S%26P_500_companies
A3: 수집 일시 | B3: 2026-09-24 18:32:58 KST
A4: 수집 성공 / 전체 | B4: 503 / 503
A5: 단위 | B5: 매출·영업이익: 백만 달러(USD mn), 성장률: %
A6: 영업이익 YoY 규칙 | B6: Q-4 영업이익 ≤ 0 → Q0 > 0 이면 '흑자전환', 아니면 'N/M' / Q-4 > 0 이고 Q0 < 0 → '적자전환'
A7: 행 정렬 기준 | B7: ① 초록: QoQ 가속(QoQ(Q0)>QoQ(Q-1)>QoQ(Q-2)>QoQ(Q-3)) 이면서 최근 QoQ≥10% (11개) → ② 노랑: 둘 중 하나만 해당 (가속 11개, QoQ≥10% 143개) — ①②는 최근 QoQ 내림차순 → ③ 나머지: 매출 YoY 내림차순(계산 불가는 맨 아래). 주요 사업은 ①② 기업에 기재 (sp500_business_ko.csv, 없으면 Yahoo 업종)
A9: 수집 실패 티커 (0개)
A10: 티커 | B10: 기업명 | C10: 오류
A11: (없음)
A13: 데이터 누락 티커 (74개)
A14: 티커 | B14: 기업명 | C14: 누락 내용
A15: BX | B15: Blackstone Inc. | C15: 영업이익 없음: Q0,Q-1,Q-2,Q-3,Q-4
A16: ES | B16: Eversource Energy | C16: Yahoo에 값 없는 최신 분기 열 제외: 2026-06-30
A17: BRK-B | B17: Berkshire Hathaway | C17: 영업이익 없음: Q0,Q-1,Q-2,Q-3,Q-4; Q0~Q-4 간격 456일(1년 아님, YoY 해석 주의)
A18: CTVA | B18: Corteva | C18: Yahoo에 값 없는 최신 분기 열 제외: 2026-06-30
A19: AEE | B19: Ameren | C19: Yahoo에 값 없는 최신 분기 열 제외: 2026-06-30
A20: LEN | B20: Lennar | C20: Yahoo에 값 없는 최신 분기 열 제외: 2026-08-31
A21: APH | B21: Amphenol | C21: Yahoo에 값 없는 최신 분기 열 제외: 2026-06-30
A22: GS | B22: Goldman Sachs | C22: 영업이익 없음: Q0,Q-1,Q-2,Q-3,Q-4
A23: FERG | B23: Ferguson Enterprises | C23: Q0~Q-4 간격 426일(1년 아님, YoY 해석 주의)
A24: DTE | B24: DTE Energy | C24: Yahoo에 값 없는 최신 분기 열 제외: 2026-06-30
A25: FITB | B25: Fifth Third Bancorp | C25: 영업이익 없음: Q0,Q-1,Q-2,Q-3,Q-4
... A88: KIM | B88: Kimco Realty | C88: 매출 없음: Q-1,Q-2,Q-3,Q-4
A90: 기업별 실제 분기 종료일
A91: 티커 | B91: 기업명 | C91: Q0 종료일 | D91: Q-1 종료일 | E91: Q-2 종료일 | F91: Q-3 종료일 | G91: Q-4 종료일 | H91: 비고
A92: A | B92: Agilent Technologies | C92: 2026-07-31 | D92: 2026-04-30 | E92: 2026-01-31 | F92: 2025-10-31 | G92: 2025-07-31
A93: AAPL | B93: Apple Inc. | C93: 2026-06-30 | D93: 2026-03-31 | E93: 2025-12-31 | F93: 2025-09-30 | G93: 2025-06-30
A94: ABBV | B94: AbbVie | C94: 2026-06-30 | D94: 2026-03-31 | E94: 2025-12-31 | F94: 2025-09-30 | G94: 2025-06-30
A95: ABNB | B95: Airbnb | C95: 2026-06-30 | D95: 2026-03-31 | E95: 2025-12-31 | F95: 2025-09-30 | G95: 2025-06-30
A96: ABT | B96: Abbott Laboratories | C96: 2026-03-31 | D96: 2025-12-31 | E96: 2025-09-30 | F96: 2025-06-30 | G96: 2025-03-31 | H96: Yahoo에 값 없는 최신 분기 열 제외: 2026-06-30
A97: ACGL | B97: Arch Capital Group | C97: 2026-06-30 | D97: 2026-03-31 | E97: 2025-12-31 | F97: 2025-09-30 | G97: 2025-06-30
A98: ACN | B98: Accenture | C98: 2026-05-31 | D98: 2026-02-28 | E98: 2025-11-30 | F98: 2025-08-31 | G98: 2025-05-31
A99: ADBE | B99: Adobe Inc. | C99: 2026-08-31 | D99: 2026-05-31 | E99: 2026-02-28 | F99: 2025-11-30 | G99: 2025-08-31
A100: ADI | B100: Analog Devices | C100: 2026-07-31 | D100: 2026-04-30 | E100: 2026-01-31 | F100: 2025-10-31 | G100: 2025-07-31
A101: ADM | B101: Archer Daniels Midland | C101: 2026-06-30 | D101: 2026-03-31 | E101: 2025-12-31 | F101: 2025-09-30 | G101: 2025-06-30
A102: ADP | B102: Automatic Data Processing | C102: 2026-06-30 | D102: 2026-03-31 | E102: 2025-12-31 | F102: 2025-09-30 | G102: 2025-06-30
A103: ADSK | B103: Autodesk | C103: 2026-07-31 | D103: 2026-04-30 | E103: 2026-01-31 | F103: 2025-10-31 | G103: 2025-07-31
A104: AEE | B104: Ameren | C104: 2026-03-31 | D104: 2025-12-31 | E104: 2025-09-30 | F104: 2025-06-30 | G104: 2025-03-31 | H104: Yahoo에 값 없는 최신 분기 열 제외: 2026-06-30
A105: AEP | B105: American Electric Power | C105: 2026-06-30 | D105: 2026-03-31 | E105: 2025-12-31 | F105: 2025-09-30 | G105: 2025-06-30
...
